Workbook
Name ListaProdutos: LISTAS!$A$2:$A$92

Sheet DADOS
A1: Código | B1: Produto | C1: Comprimento | D1: Largura | E1: Altura | F1: Descr.Familia
A2: 10012001 | B2: LATERAL 756X336X15 MDP - APARADOR TANGER | C2: 0.756 | D2: 0.336 | E2: 0.015 | F2: PEÇAS
A3: 10012002 | B3: TAMPO INFERIOR 1198X336X12 MDP - APARADOR TANGER | C3: 1.198 | D3: 0.336 | E3: 0.012 | F3: PEÇAS
A4: 10012003 | B4: TRAVESSA CENTRAL 1163X222X12 MDP - APARADOR TANGER | C4: 1.163 | D4: 0.222 | E4: 0.012 | F4: PEÇAS
A5: 10012004 | B5: APOIO TMP 1098X60(128)X12 MDP (2PC) US6,2 - TANGER | C5: 1.098 | D5: 0.064 | E5: 0.012 | F5: PEÇAS
A6: 10012005 | B6: MOLDURA MENOR 770X60 (260)X12 MDF (4PC) – TANGER | C6: 0.77 | D6: 0.065 | E6: 0.012 | F6: PEÇAS
A7: 10012006 | B7: MOLDURA MAIOR 1077X61X12 MDF - APARADOR TANGER | C7: 1.077 | D7: 0.061 | E7: 0.012 | F7: PEÇAS
A8: 10012007 | B8: TAMPO 1202X362X15 MDP - APARADOR TANGER | C8: 1.202 | D8: 0.362 | E8: 0.015 | F8: PEÇAS
A9: 10013502 | B9: TAMPO INFERIOR 1352X336X12 MDP - APARADOR TANGER | C9: 1.352 | D9: 0.336 | E9: 0.012 | F9: PEÇAS
A10: 10013503 | B10: TRAVESSA CENTRAL 1324X222X12 MDP - APARADOR TANGER | C10: 1.324 | D10: 0.222 | E10: 0.012 | F10: PEÇAS
A11: 10013504 | B11: APOIO TAMPO 1352X62X12 MDP - APARADOR TANGER | C11: 1.352 | D11: 0.062 | E11: 0.012 | F11: PEÇAS
A12: 10013506 | B12: MOLDURA MAIOR 1232X61X12 MDF - APARADOR TANGER | C12: 1.232 | D12: 0.061 | E12: 0.012 | F12: PEÇAS
A13: 10013507 | B13: TAMPO 1352X362X15 MDP - APARADOR TANGER | C13: 1.352 | D13: 0.362 | E13: 0.015 | F13: PEÇAS
... A1507: 99010005 | B1507: ESPUMA CASCÃO 550X210X30 D30 - PAINEL MODULADO | C1507: 0.6 | D1507: 0.41 | E1507: 0.02 | F1507: PEÇAS

Sheet CALCULO_LOTE
A2: Data | B2: 46137
A3: Produtos totais | B3: =SUM(C10:C59) -> 0
A4: m² total cortado | B4: =SUM(Y10:Y21) -> 0
A5: Chapas totais estimadas | B5: =SUM(AD10:AD21) -> 0
A6: Peças totais | B6: =SUM(X10:X21) -> 0
A7: Produtos diferentes | B7: =COUNTIF(B10:B59,"<>") -> 0
A9: Item | B9: Produto agregado / completo | C9: Qtde produtos | D9: Peças unit. | E9: m² unit. | F9: m² do lote | G9: IDX | H9: Produto | I9: Qtde prod. | J9: Código | K9: Peça | L9: Comp. (m) | M9: Larg. (m) | N9: Esp. (mm) | O9: Material | P9: Tipo chapa | Q9: Qtde peça/prod. | R9: Qtde peças lote | S9: m² lote | T9: Produto original | V9: Tipo chapa | W9: Medida chapa | X9: Qtde peças lote | Y9: m² cortado | Z9: Comp. chapa (m) | AA9: Larg. chapa (m) | AB9: Aproveit. | AC9: m² útil/chapa | AD9: Qtde chapas usadas
A10: 1 | D10: =IFERROR(VLOOKUP(B10,LISTAS!$A:$C,2,FALSE()),"") | E10: =IFERROR(VLOOKUP(B10,LISTAS!$A:$C,3,FALSE()),0) -> 0 | F10: =IFERROR(C10*E10,0) -> 0 | G10: =IFERROR(_xludf.aggregate(15,6,(ROW(BASE_PRODUTOS!$L$2:$L$1006)-ROW(BASE_PRODUTOS!$L$2)+1)/(BASE_PRODUTOS!$L$2:$L$1006>0),ROWS($G$10:G10)),"") | H10: =IF($G10="","",INDEX(BASE_PRODUTOS!$B$2:$B$1006,$G10)) | I10: =IF($G10="","",INDEX(BASE_PRODUTOS!$L$2:$L$1006,$G10)) | J10: =IF($G10="","",INDEX(BASE_PRODUTOS!$A$2:$A$1006,$G10)) | K10: =IF($G10="","",INDEX(BASE_PRODUTOS!$C$2:$C$1006,$G10)) | L10: =IF($G10="","",INDEX(BASE_PRODUTOS!$E$2:$E$1006,$G10)) | M10: =IF($G10="","",INDEX(BASE_PRODUTOS!$F$2:$F$1006,$G10)) | N10: =IF($G10="","",INDEX(BASE_PRODUTOS!$G$2:$G$1006,$G10)) | O10: =IF($G10="","",INDEX(BASE_PRODUTOS!$H$2:$H$1006,$G10)) | P10: =IF($G10="","",INDEX(BASE_PRODUTOS!$I$2:$I$1006,$G10)) | Q10: =IF($G10="","",INDEX(BASE_PRODUTOS!$J$2:$J$1006,$G10)) | R10: =IF($G10="","",INDEX(BASE_PRODUTOS!$M$2:$M$1006,$G10)) | S10: =IF($G10="","",INDEX(BASE_PRODUTOS!$N$2:$N$1006,$G10)) | T10: =IF($G10="","",INDEX(BASE_PRODUTOS!$D$2:$D$1006,$G10)) | V10: MDF 9mm | W10: =IF($V10="","",TEXT($Z10,"0.00")&" x "&TEXT($AA10,"0.00")&" m") -> 003 x 002 m | X10: =IF($V10="","",SUMIF(BASE_PRODUTOS!$I:$I,$V10,BASE_PRODUTOS!$M:$M)) -> 0 | Y10: =IF($V10="","",SUMIF(BASE_PRODUTOS!$I:$I,$V10,BASE_PRODUTOS!$N:$N)) -> 0 | Z10: 2.75 | AA10: 1.85 | AB10: 0.95 | AC10: =IFERROR($Z10*$AA10*$AB10,0) -> 4.833125 | AD10: =IFERROR(IF($Y10>0,ROUNDUP($Y10/$AC10,0),0),0) -> 0
A11: 2 | D11: =IFERROR(VLOOKUP(B11,LISTAS!$A:$C,2,FALSE()),"") | E11: =IFERROR(VLOOKUP(B11,LISTAS!$A:$C,3,FALSE()),0) -> 0 | F11: =IFERROR(C11*E11,0) -> 0 | G11: =IFERROR(_xludf.aggregate(15,6,(ROW(BASE_PRODUTOS!$L$2:$L$1006)-ROW(BASE_PRODUTOS!$L$2)+1)/(BASE_PRODUTOS!$L$2:$L$1006>0),ROWS($G$10:G11)),"") | H11: =IF($G11="","",INDEX(BASE_PRODUTOS!$B$2:$B$1006,$G11)) | I11: =IF($G11="","",INDEX(BASE_PRODUTOS!$L$2:$L$1006,$G11)) | J11: =IF($G11="","",INDEX(BASE_PRODUTOS!$A$2:$A$1006,$G11)) | K11: =IF($G11="","",INDEX(BASE_PRODUTOS!$C$2:$C$1006,$G11)) | L11: =IF($G11="","",INDEX(BASE_PRODUTOS!$E$2:$E$1006,$G11)) | M11: =IF($G11="","",INDEX(BASE_PRODUTOS!$F$2:$F$1006,$G11)) | N11: =IF($G11="","",INDEX(BASE_PRODUTOS!$G$2:$G$1006,$G11)) | O11: =IF($G11="","",INDEX(BASE_PRODUTOS!$H$2:$H$1006,$G11)) | P11: =IF($G11="","",INDEX(BASE_PRODUTOS!$I$2:$I$1006,$G11)) | Q11: =IF($G11="","",INDEX(BASE_PRODUTOS!$J$2:$J$1006,$G11)) | R11: =IF($G11="","",INDEX(BASE_PRODUTOS!$M$2:$M$1006,$G11)) | S11: =IF($G11="","",INDEX(BASE_PRODUTOS!$N$2:$N$1006,$G11)) | T11: =IF($G11="","",INDEX(BASE_PRODUTOS!$D$2:$D$1006,$G11)) | V11: MDF 25mm | W11: =IF($V11="","",TEXT($Z11,"0.00")&" x "&TEXT($AA11,"0.00")&" m") -> 003 x 002 m | X11: =IF($V11="","",SUMIF(BASE_PRODUTOS!$I:$I,$V11,BASE_PRODUTOS!$M:$M)) -> 0 | Y11: =IF($V11="","",SUMIF(BASE_PRODUTOS!$I:$I,$V11,BASE_PRODUTOS!$N:$N)) -> 0 | Z11: 2.75 | AA11: 1.85 | AB11: 0.95 | AC11: =IFERROR($Z11*$AA11*$AB11,0) -> 4.833125 | AD11: =IFERROR(IF($Y11>0,ROUNDUP($Y11/$AC11,0),0),0) -> 0
A12: 3 | D12: =IFERROR(VLOOKUP(B12,LISTAS!$A:$C,2,FALSE()),"") | E12: =IFERROR(VLOOKUP(B12,LISTAS!$A:$C,3,FALSE()),0) -> 0 | F12: =IFERROR(C12*E12,0) -> 0 | G12: =IFERROR(_xludf.aggregate(15,6,(ROW(BASE_PRODUTOS!$L$2:$L$1006)-ROW(BASE_PRODUTOS!$L$2)+1)/(BASE_PRODUTOS!$L$2:$L$1006>0),ROWS($G$10:G12)),"") | H12: =IF($G12="","",INDEX(BASE_PRODUTOS!$B$2:$B$1006,$G12)) | I12: =IF($G12="","",INDEX(BASE_PRODUTOS!$L$2:$L$1006,$G12)) | J12: =IF($G12="","",INDEX(BASE_PRODUTOS!$A$2:$A$1006,$G12)) | K12: =IF($G12="","",INDEX(BASE_PRODUTOS!$C$2:$C$1006,$G12)) | L12: =IF($G12="","",INDEX(BASE_PRODUTOS!$E$2:$E$1006,$G12)) | M12: =IF($G12="","",INDEX(BASE_PRODUTOS!$F$2:$F$1006,$G12)) | N12: =IF($G12="","",INDEX(BASE_PRODUTOS!$G$2:$G$1006,$G12)) | O12: =IF($G12="","",INDEX(BASE_PRODUTOS!$H$2:$H$1006,$G12)) | P12: =IF($G12="","",INDEX(BASE_PRODUTOS!$I$2:$I$1006,$G12)) | Q12: =IF($G12="","",INDEX(BASE_PRODUTOS!$J$2:$J$1006,$G12)) | R12: =IF($G12="","",INDEX(BASE_PRODUTOS!$M$2:$M$1006,$G12)) | S12: =IF($G12="","",INDEX(BASE_PRODUTOS!$N$2:$N$1006,$G12)) | T12: =IF($G12="","",INDEX(BASE_PRODUTOS!$D$2:$D$1006,$G12)) | V12: MDF 18mm | W12: =IF($V12="","",TEXT($Z12,"0.00")&" x "&TEXT($AA12,"0.00")&" m") -> 003 x 002 m | X12: =IF($V12="","",SUMIF(BASE_PRODUTOS!$I:$I,$V12,BASE_PRODUTOS!$M:$M)) -> 0 | Y12: =IF($V12="","",SUMIF(BASE_PRODUTOS!$I:$I,$V12,BASE_PRODUTOS!$N:$N)) -> 0 | Z12: 2.75 | AA12: 1.85 | AB12: 0.95 | AC12: =IFERROR($Z12*$AA12*$AB12,0) -> 4.833125 | AD12: =IFERROR(IF($Y12>0,ROUNDUP($Y12/$AC12,0),0),0) -> 0
A13: 4 | D13: =IFERROR(VLOOKUP(B13,LISTAS!$A:$C,2,FALSE()),"") | E13: =IFERROR(VLOOKUP(B13,LISTAS!$A:$C,3,FALSE()),0) -> 0 | F13: =IFERROR(C13*E13,0) -> 0 | G13: =IFERROR(_xludf.aggregate(15,6,(ROW(BASE_PRODUTOS!$L$2:$L$1006)-ROW(BASE_PRODUTOS!$L$2)+1)/(BASE_PRODUTOS!$L$2:$L$1006>0),ROWS($G$10:G13)),"") | H13: =IF($G13="","",INDEX(BASE_PRODUTOS!$B$2:$B$1006,$G13)) | I13: =IF($G13="","",INDEX(BASE_PRODUTOS!$L$2:$L$1006,$G13)) | J13: =IF($G13="","",INDEX(BASE_PRODUTOS!$A$2:$A$1006,$G13)) | K13: =IF($G13="","",INDEX(BASE_PRODUTOS!$C$2:$C$1006,$G13)) | L13: =IF($G13="","",INDEX(BASE_PRODUTOS!$E$2:$E$1006,$G13)) | M13: =IF($G13="","",INDEX(BASE_PRODUTOS!$F$2:$F$1006,$G13)) | N13: =IF($G13="","",INDEX(BASE_PRODUTOS!$G$2:$G$1006,$G13)) | O13: =IF($G13="","",INDEX(BASE_PRODUTOS!$H$2:$H$1006,$G13)) | P13: =IF($G13="","",INDEX(BASE_PRODUTOS!$I$2:$I$1006,$G13)) | Q13: =IF($G13="","",INDEX(BASE_PRODUTOS!$J$2:$J$1006,$G13)) | R13: =IF($G13="","",INDEX(BASE_PRODUTOS!$M$2:$M$1006,$G13)) | S13: =IF($G13="","",INDEX(BASE_PRODUTOS!$N$2:$N$1006,$G13)) | T13: =IF($G13="","",INDEX(BASE_PRODUTOS!$D$2:$D$1006,$G13)) | V13: MDF 15mm | W13: =IF($V13="","",TEXT($Z13,"0.00")&" x "&TEXT($AA13,"0.00")&" m") -> 003 x 002 m | X13: =IF($V13="","",SUMIF(BASE_PRODUTOS!$I:$I,$V13,BASE_PRODUTOS!$M:$M)) -> 0 | Y13: =IF($V13="","",SUMIF(BASE_PRODUTOS!$I:$I,$V13,BASE_PRODUTOS!$N:$N)) -> 0 | Z13: 2.75 | AA13: 1.85 | AB13: 0.95 | AC13: =IFERROR($Z13*$AA13*$AB13,0) -> 4.833125 | AD13: =IFERROR(IF($Y13>0,ROUNDUP($Y13/$AC13,0),0),0) -> 0
A14: 5 | D14: =IFERROR(VLOOKUP(B14,LISTAS!$A:$C,2,FALSE()),"") | E14: =IFERROR(VLOOKUP(B14,LISTAS!$A:$C,3,FALSE()),0) -> 0 | F14: =IFERROR(C14*E14,0) -> 0 | G14: =IFERROR(_xludf.aggregate(15,6,(ROW(BASE_PRODUTOS!$L$2:$L$1006)-ROW(BASE_PRODUTOS!$L$2)+1)/(BASE_PRODUTOS!$L$2:$L$1006>0),ROWS($G$10:G14)),"") | H14: =IF($G14="","",INDEX(BASE_PRODUTOS!$B$2:$B$1006,$G14)) | I14: =IF($G14="","",INDEX(BASE_PRODUTOS!$L$2:$L$1006,$G14)) | J14: =IF($G14="","",INDEX(BASE_PRODUTOS!$A$2:$A$1006,$G14)) | K14: =IF($G14="","",INDEX(BASE_PRODUTOS!$C$2:$C$1006,$G14)) | L14: =IF($G14="","",INDEX(BASE_PRODUTOS!$E$2:$E$1006,$G14)) | M14: =IF($G14="","",INDEX(BASE_PRODUTOS!$F$2:$F$1006,$G14)) | N14: =IF($G14="","",INDEX(BASE_PRODUTOS!$G$2:$G$1006,$G14)) | O14: =IF($G14="","",INDEX(BASE_PRODUTOS!$H$2:$H$1006,$G14)) | P14: =IF($G14="","",INDEX(BASE_PRODUTOS!$I$2:$I$1006,$G14)) | Q14: =IF($G14="","",INDEX(BASE_PRODUTOS!$J$2:$J$1006,$G14)) | R14: =IF($G14="","",INDEX(BASE_PRODUTOS!$M$2:$M$1006,$G14)) | S14: =IF($G14="","",INDEX(BASE_PRODUTOS!$N$2:$N$1006,$G14)) | T14: =IF($G14="","",INDEX(BASE_PRODUTOS!$D$2:$D$1006,$G14)) | V14: MDP 12mm | W14: =IF($V14="","",TEXT($Z14,"0.00")&" x "&TEXT($AA14,"0.00")&" m") -> 003 x 002 m | X14: =IF($V14="","",SUMIF(BASE_PRODUTOS!$I:$I,$V14,BASE_PRODUTOS!$M:$M)) -> 0 | Y14: =IF($V14="","",SUMIF(BASE_PRODUTOS!$I:$I,$V14,BASE_PRODUTOS!$N:$N)) -> 0 | Z14: 2.75 | AA14: 1.85 | AB14: 0.95 | AC14: =IFERROR($Z14*$AA14*$AB14,0) -> 4.833125 | AD14: =IFERROR(IF($Y14>0,ROUNDUP($Y14/$AC14,0),0),0) -> 0
A15: 6 | D15: =IFERROR(VLOOKUP(B15,LISTAS!$A:$C,2,FALSE()),"") | E15: =IFERROR(VLOOKUP(B15,LISTAS!$A:$C,3,FALSE()),0) -> 0 | F15: =IFERROR(C15*E15,0) -> 0 | G15: =IFERROR(_xludf.aggregate(15,6,(ROW(BASE_PRODUTOS!$L$2:$L$1006)-ROW(BASE_PRODUTOS!$L$2)+1)/(BASE_PRODUTOS!$L$2:$L$1006>0),ROWS($G$10:G15)),"") | H15: =IF($G15="","",INDEX(BASE_PRODUTOS!$B$2:$B$1006,$G15)) | I15: =IF($G15="","",INDEX(BASE_PRODUTOS!$L$2:$L$1006,$G15)) | J15: =IF($G15="","",INDEX(BASE_PRODUTOS!$A$2:$A$1006,$G15)) | K15: =IF($G15="","",INDEX(BASE_PRODUTOS!$C$2:$C$1006,$G15)) | L15: =IF($G15="","",INDEX(BASE_PRODUTOS!$E$2:$E$1006,$G15)) | M15: =IF($G15="","",INDEX(BASE_PRODUTOS!$F$2:$F$1006,$G15)) | N15: =IF($G15="","",INDEX(BASE_PRODUTOS!$G$2:$G$1006,$G15)) | O15: =IF($G15="","",INDEX(BASE_PRODUTOS!$H$2:$H$1006,$G15)) | P15: =IF($G15="","",INDEX(BASE_PRODUTOS!$I$2:$I$1006,$G15)) | Q15: =IF($G15="","",INDEX(BASE_PRODUTOS!$J$2:$J$1006,$G15)) | R15: =IF($G15="","",INDEX(BASE_PRODUTOS!$M$2:$M$1006,$G15)) | S15: =IF($G15="","",INDEX(BASE_PRODUTOS!$N$2:$N$1006,$G15)) | T15: =IF($G15="","",INDEX(BASE_PRODUTOS!$D$2:$D$1006,$G15)) | V15: MDP 9mm | W15: =IF($V15="","",TEXT($Z15,"0.00")&" x "&TEXT($AA15,"0.00")&" m") -> 003 x 002 m | X15: =IF($V15="","",SUMIF(BASE_PRODUTOS!$I:$I,$V15,BASE_PRODUTOS!$M:$M)) -> 0 | Y15: =IF($V15="","",SUMIF(BASE_PRODUTOS!$I:$I,$V15,BASE_PRODUTOS!$N:$N)) -> 0 | Z15: 2.75 | AA15: 1.85 | AB15: 0.95 | AC15: =IFERROR($Z15*$AA15*$AB15,0) -> 4.833125 | AD15: =IFERROR(IF($Y15>0,ROUNDUP($Y15/$AC15,0),0),0) -> 0
A16: 7 | D16: =IFERROR(VLOOKUP(B16,LISTAS!$A:$C,2,FALSE()),"") | E16: =IFERROR(VLOOKUP(B16,LISTAS!$A:$C,3,FALSE()),0) -> 0 | F16: =IFERROR(C16*E16,0) -> 0 | G16: =IFERROR(_xludf.aggregate(15,6,(ROW(BASE_PRODUTOS!$L$2:$L$1006)-ROW(BASE_PRODUTOS!$L$2)+1)/(BASE_PRODUTOS!$L$2:$L$1006>0),ROWS($G$10:G16)),"") | H16: =IF($G16="","",INDEX(BASE_PRODUTOS!$B$2:$B$1006,$G16)) | I16: =IF($G16="","",INDEX(BASE_PRODUTOS!$L$2:$L$1006,$G16)) | J16: =IF($G16="","",INDEX(BASE_PRODUTOS!$A$2:$A$1006,$G16)) | K16: =IF($G16="","",INDEX(BASE_PRODUTOS!$C$2:$C$1006,$G16)) | L16: =IF($G16="","",INDEX(BASE_PRODUTOS!$E$2:$E$1006,$G16)) | M16: =IF($G16="","",INDEX(BASE_PRODUTOS!$F$2:$F$1006,$G16)) | N16: =IF($G16="","",INDEX(BASE_PRODUTOS!$G$2:$G$1006,$G16)) | O16: =IF($G16="","",INDEX(BASE_PRODUTOS!$H$2:$H$1006,$G16)) | P16: =IF($G16="","",INDEX(BASE_PRODUTOS!$I$2:$I$1006,$G16)) | Q16: =IF($G16="","",INDEX(BASE_PRODUTOS!$J$2:$J$1006,$G16)) | R16: =IF($G16="","",INDEX(BASE_PRODUTOS!$M$2:$M$1006,$G16)) | S16: =IF($G16="","",INDEX(BASE_PRODUTOS!$N$2:$N$1006,$G16)) | T16: =IF($G16="","",INDEX(BASE_PRODUTOS!$D$2:$D$1006,$G16)) | V16: MDP 15mm | W16: =IF($V16="","",TEXT($Z16,"0.00")&" x "&TEXT($AA16,"0.00")&" m") -> 003 x 002 m | X16: =IF($V16="","",SUMIF(BASE_PRODUTOS!$I:$I,$V16,BASE_PRODUTOS!$M:$M)) -> 0 | Y16: =IF($V16="","",SUMIF(BASE_PRODUTOS!$I:$I,$V16,BASE_PRODUTOS!$N:$N)) -> 0 | Z16: 2.75 | AA16: 1.85 | AB16: 0.95 | AC16: =IFERROR($Z16*$AA16*$AB16,0) -> 4.833125 | AD16: =IFERROR(IF($Y16>0,ROUNDUP($Y16/$AC16,0),0),0) -> 0
A17: 8 | D17: =IFERROR(VLOOKUP(B17,LISTAS!$A:$C,2,FALSE()),"") | E17: =IFERROR(VLOOKUP(B17,LISTAS!$A:$C,3,FALSE()),0) -> 0 | F17: =IFERROR(C17*E17,0) -> 0 | G17: =IFERROR(_xludf.aggregate(15,6,(ROW(BASE_PRODUTOS!$L$2:$L$1006)-ROW(BASE_PRODUTOS!$L$2)+1)/(BASE_PRODUTOS!$L$2:$L$1006>0),ROWS($G$10:G17)),"") | H17: =IF($G17="","",INDEX(BASE_PRODUTOS!$B$2:$B$1006,$G17)) | I17: =IF($G17="","",INDEX(BASE_PRODUTOS!$L$2:$L$1006,$G17)) | J17: =IF($G17="","",INDEX(BASE_PRODUTOS!$A$2:$A$1006,$G17)) | K17: =IF($G17="","",INDEX(BASE_PRODUTOS!$C$2:$C$1006,$G17)) | L17: =IF($G17="","",INDEX(BASE_PRODUTOS!$E$2:$E$1006,$G17)) | M17: =IF($G17="","",INDEX(BASE_PRODUTOS!$F$2:$F$1006,$G17)) | N17: =IF($G17="","",INDEX(BASE_PRODUTOS!$G$2:$G$1006,$G17)) | O17: =IF($G17="","",INDEX(BASE_PRODUTOS!$H$2:$H$1006,$G17)) | P17: =IF($G17="","",INDEX(BASE_PRODUTOS!$I$2:$I$1006,$G17)) | Q17: =IF($G17="","",INDEX(BASE_PRODUTOS!$J$2:$J$1006,$G17)) | R17: =IF($G17="","",INDEX(BASE_PRODUTOS!$M$2:$M$1006,$G17)) | S17: =IF($G17="","",INDEX(BASE_PRODUTOS!$N$2:$N$1006,$G17)) | T17: =IF($G17="","",INDEX(BASE_PRODUTOS!$D$2:$D$1006,$G17)) | V17: MDP 25mm | W17: =IF($V17="","",TEXT($Z17,"0.00")&" x "&TEXT($AA17,"0.00")&" m") -> 003 x 002 m | X17: =IF($V17="","",SUMIF(BASE_PRODUTOS!$I:$I,$V17,BASE_PRODUTOS!$M:$M)) -> 0 | Y17: =IF($V17="","",SUMIF(BASE_PRODUTOS!$I:$I,$V17,BASE_PRODUTOS!$N:$N)) -> 0 | Z17: 2.75 | AA17: 1.85 | AB17: 0.95 | AC17: =IFERROR($Z17*$AA17*$AB17,0) -> 4.833125 | AD17: =IFERROR(IF($Y17>0,ROUNDUP($Y17/$AC17,0),0),0) -> 0
A18: 9 | D18: =IFERROR(VLOOKUP(B18,LISTAS!$A:$C,2,FALSE()),"") | E18: =IFERROR(VLOOKUP(B18,LISTAS!$A:$C,3,FALSE()),0) -> 0 | F18: =IFERROR(C18*E18,0) -> 0 | G18: =IFERROR(_xludf.aggregate(15,6,(ROW(BASE_PRODUTOS!$L$2:$L$1006)-ROW(BASE_PRODUTOS!$L$2)+1)/(BASE_PRODUTOS!$L$2:$L$1006>0),ROWS($G$10:G18)),"") | H18: =IF($G18="","",INDEX(BASE_PRODUTOS!$B$2:$B$1006,$G18)) | I18: =IF($G18="","",INDEX(BASE_PRODUTOS!$L$2:$L$1006,$G18)) | J18: =IF($G18="","",INDEX(BASE_PRODUTOS!$A$2:$A$1006,$G18)) | K18: =IF($G18="","",INDEX(BASE_PRODUTOS!$C$2:$C$1006,$G18)) | L18: =IF($G18="","",INDEX(BASE_PRODUTOS!$E$2:$E$1006,$G18)) | M18: =IF($G18="","",INDEX(BASE_PRODUTOS!$F$2:$F$1006,$G18)) | N18: =IF($G18="","",INDEX(BASE_PRODUTOS!$G$2:$G$1006,$G18)) | O18: =IF($G18="","",INDEX(BASE_PRODUTOS!$H$2:$H$1006,$G18)) | P18: =IF($G18="","",INDEX(BASE_PRODUTOS!$I$2:$I$1006,$G18)) | Q18: =IF($G18="","",INDEX(BASE_PRODUTOS!$J$2:$J$1006,$G18)) | R18: =IF($G18="","",INDEX(BASE_PRODUTOS!$M$2:$M$1006,$G18)) | S18: =IF($G18="","",INDEX(BASE_PRODUTOS!$N$2:$N$1006,$G18)) | T18: =IF($G18="","",INDEX(BASE_PRODUTOS!$D$2:$D$1006,$G18)) | V18: HDF 9mm | W18: =IF($V18="","",TEXT($Z18,"0.00")&" x "&TEXT($AA18,"0.00")&" m") -> 003 x 002 m | X18: =IF($V18="","",SUMIF(BASE_PRODUTOS!$I:$I,$V18,BASE_PRODUTOS!$M:$M)) -> 0 | Y18: =IF($V18="","",SUMIF(BASE_PRODUTOS!$I:$I,$V18,BASE_PRODUTOS!$N:$N)) -> 0 | Z18: 2.75 | AA18: 1.85 | AB18: 0.95 | AC18: =IFERROR($Z18*$AA18*$AB18,0) -> 4.833125 | AD18: =IFERROR(IF($Y18>0,ROUNDUP($Y18/$AC18,0),0),0) -> 0
A19: 10 | D19: =IFERROR(VLOOKUP(B19,LISTAS!$A:$C,2,FALSE()),"") | E19: =IFERROR(VLOOKUP(B19,LISTAS!$A:$C,3,FALSE()),0) -> 0 | F19: =IFERROR(C19*E19,0) -> 0 | G19: =IFERROR(_xludf.aggregate(15,6,(ROW(BASE_PRODUTOS!$L$2:$L$1006)-ROW(BASE_PRODUTOS!$L$2)+1)/(BASE_PRODUTOS!$L$2:$L$1006>0),ROWS($G$10:G19)),"") | H19: =IF($G19="","",INDEX(BASE_PRODUTOS!$B$2:$B$1006,$G19)) | I19: =IF($G19="","",INDEX(BASE_PRODUTOS!$L$2:$L$1006,$G19)) | J19: =IF($G19="","",INDEX(BASE_PRODUTOS!$A$2:$A$1006,$G19)) | K19: =IF($G19="","",INDEX(BASE_PRODUTOS!$C$2:$C$1006,$G19)) | L19: =IF($G19="","",INDEX(BASE_PRODUTOS!$E$2:$E$1006,$G19)) | M19: =IF($G19="","",INDEX(BASE_PRODUTOS!$F$2:$F$1006,$G19)) | N19: =IF($G19="","",INDEX(BASE_PRODUTOS!$G$2:$G$1006,$G19)) | O19: =IF($G19="","",INDEX(BASE_PRODUTOS!$H$2:$H$1006,$G19)) | P19: =IF($G19="","",INDEX(BASE_PRODUTOS!$I$2:$I$1006,$G19)) | Q19: =IF($G19="","",INDEX(BASE_PRODUTOS!$J$2:$J$1006,$G19)) | R19: =IF($G19="","",INDEX(BASE_PRODUTOS!$M$2:$M$1006,$G19)) | S19: =IF($G19="","",INDEX(BASE_PRODUTOS!$N$2:$N$1006,$G19)) | T19: =IF($G19="","",INDEX(BASE_PRODUTOS!$D$2:$D$1006,$G19)) | V19: MDF 3mm | W19: =IF($V19="","",TEXT($Z19,"0.00")&" x "&TEXT($AA19,"0.00")&" m") -> 003 x 002 m | X19: =IF($V19="","",SUMIF(BASE_PRODUTOS!$I:$I,$V19,BASE_PRODUTOS!$M:$M)) -> 0 | Y19: =IF($V19="","",SUMIF(BASE_PRODUTOS!$I:$I,$V19,BASE_PRODUTOS!$N:$N)) -> 0 | Z19: 2.75 | AA19: 1.85 | AB19: 0.95 | AC19: =IFERROR($Z19*$AA19*$AB19,0) -> 4.833125 | AD19: =IFERROR(IF($Y19>0,ROUNDUP($Y19/$AC19,0),0),0) -> 0
A20: 11 | D20: =IFERROR(VLOOKUP(B20,LISTAS!$A:$C,2,FALSE()),"") | E20: =IFERROR(VLOOKUP(B20,LISTAS!$A:$C,3,FALSE()),0) -> 0 | F20: =IFERROR(C20*E20,0) -> 0 | G20: =IFERROR(_xludf.aggregate(15,6,(ROW(BASE_PRODUTOS!$L$2:$L$1006)-ROW(BASE_PRODUTOS!$L$2)+1)/(BASE_PRODUTOS!$L$2:$L$1006>0),ROWS($G$10:G20)),"") | H20: =IF($G20="","",INDEX(BASE_PRODUTOS!$B$2:$B$1006,$G20)) | I20: =IF($G20="","",INDEX(BASE_PRODUTOS!$L$2:$L$1006,$G20)) | J20: =IF($G20="","",INDEX(BASE_PRODUTOS!$A$2:$A$1006,$G20)) | K20: =IF($G20="","",INDEX(BASE_PRODUTOS!$C$2:$C$1006,$G20)) | L20: =IF($G20="","",INDEX(BASE_PRODUTOS!$E$2:$E$1006,$G20)) | M20: =IF($G20="","",INDEX(BASE_PRODUTOS!$F$2:$F$1006,$G20)) | N20: =IF($G20="","",INDEX(BASE_PRODUTOS!$G$2:$G$1006,$G20)) | O20: =IF($G20="","",INDEX(BASE_PRODUTOS!$H$2:$H$1006,$G20)) | P20: =IF($G20="","",INDEX(BASE_PRODUTOS!$I$2:$I$1006,$G20)) | Q20: =IF($G20="","",INDEX(BASE_PRODUTOS!$J$2:$J$1006,$G20)) | R20: =IF($G20="","",INDEX(BASE_PRODUTOS!$M$2:$M$1006,$G20)) | S20: =IF($G20="","",INDEX(BASE_PRODUTOS!$N$2:$N$1006,$G20)) | T20: =IF($G20="","",INDEX(BASE_PRODUTOS!$D$2:$D$1006,$G20)) | V20: MDF 12mm | W20: =IF($V20="","",TEXT($Z20,"0.00")&" x "&TEXT($AA20,"0.00")&" m") -> 003 x 002 m | X20: =IF($V20="","",SUMIF(BASE_PRODUTOS!$I:$I,$V20,BASE_PRODUTOS!$M:$M)) -> 0 | Y20: =IF($V20="","",SUMIF(BASE_PRODUTOS!$I:$I,$V20,BASE_PRODUTOS!$N:$N)) -> 0 | Z20: 2.75 | AA20: 1.85 | AB20: 0.95 | AC20: =IFERROR($Z20*$AA20*$AB20,0) -> 4.833125 | AD20: =IFERROR(IF($Y20>0,ROUNDUP($Y20/$AC20,0),0),0) -> 0
A21: 12 | D21: =IFERROR(VLOOKUP(B21,LISTAS!$A:$C,2,FALSE()),"") | E21: =IFERROR(VLOOKUP(B21,LISTAS!$A:$C,3,FALSE()),0) -> 0 | F21: =IFERROR(C21*E21,0) -> 0 | G21: =IFERROR(_xludf.aggregate(15,6,(ROW(BASE_PRODUTOS!$L$2:$L$1006)-ROW(BASE_PRODUTOS!$L$2)+1)/(BASE_PRODUTOS!$L$2:$L$1006>0),ROWS($G$10:G21)),"") | H21: =IF($G21="","",INDEX(BASE_PRODUTOS!$B$2:$B$1006,$G21)) | I21: =IF($G21="","",INDEX(BASE_PRODUTOS!$L$2:$L$1006,$G21)) | J21: =IF($G21="","",INDEX(BASE_PRODUTOS!$A$2:$A$1006,$G21)) | K21: =IF($G21="","",INDEX(BASE_PRODUTOS!$C$2:$C$1006,$G21)) | L21: =IF($G21="","",INDEX(BASE_PRODUTOS!$E$2:$E$1006,$G21)) | M21: =IF($G21="","",INDEX(BASE_PRODUTOS!$F$2:$F$1006,$G21)) | N21: =IF($G21="","",INDEX(BASE_PRODUTOS!$G$2:$G$1006,$G21)) | O21: =IF($G21="","",INDEX(BASE_PRODUTOS!$H$2:$H$1006,$G21)) | P21: =IF($G21="","",INDEX(BASE_PRODUTOS!$I$2:$I$1006,$G21)) | Q21: =IF($G21="","",INDEX(BASE_PRODUTOS!$J$2:$J$1006,$G21)) | R21: =IF($G21="","",INDEX(BASE_PRODUTOS!$M$2:$M$1006,$G21)) | S21: =IF($G21="","",INDEX(BASE_PRODUTOS!$N$2:$N$1006,$G21)) | T21: =IF($G21="","",INDEX(BASE_PRODUTOS!$D$2:$D$1006,$G21)) | V21: =IFERROR(INDEX(LISTAS!$G:$G,37),"") -> 0 | W21: =IF($V21="","",TEXT($Z21,"0.00")&" x "&TEXT($AA21,"0.00")&" m") -> 003 x 002 m | X21: =IF($V21="","",SUMIF(BASE_PRODUTOS!$I:$I,$V21,BASE_PRODUTOS!$M:$M)) -> 0 | Y21: =IF($V21="","",SUMIF(BASE_PRODUTOS!$I:$I,$V21,BASE_PRODUTOS!$N:$N)) -> 0 | Z21: 2.75 | AA21: 1.85 | AB21: 0.95 | AC21: =IFERROR($Z21*$AA21*$AB21,0) -> 4.833125 | AD21: =IFERROR(IF($Y21>0,ROUNDUP($Y21/$AC21,0),0),0) -> 0
A22: 13 | D22: =IFERROR(VLOOKUP(B22,LISTAS!$A:$C,2,FALSE()),"") | E22: =IFERROR(VLOOKUP(B22,LISTAS!$A:$C,3,FALSE()),0) -> 0 | F22: =IFERROR(C22*E22,0) -> 0 | G22: =IFERROR(_xludf.aggregate(15,6,(ROW(BASE_PRODUTOS!$L$2:$L$1006)-ROW(BASE_PRODUTOS!$L$2)+1)/(BASE_PRODUTOS!$L$2:$L$1006>0),ROWS($G$10:G22)),"") | H22: =IF($G22="","",INDEX(BASE_PRODUTOS!$B$2:$B$1006,$G22)) | I22: =IF($G22="","",INDEX(BASE_PRODUTOS!$L$2:$L$1006,$G22)) | J22: =IF($G22="","",INDEX(BASE_PRODUTOS!$A$2:$A$1006,$G22)) | K22: =IF($G22="","",INDEX(BASE_PRODUTOS!$C$2:$C$1006,$G22)) | L22: =IF($G22="","",INDEX(BASE_PRODUTOS!$E$2:$E$1006,$G22)) | M22: =IF($G22="","",INDEX(BASE_PRODUTOS!$F$2:$F$1006,$G22)) | N22: =IF($G22="","",INDEX(BASE_PRODUTOS!$G$2:$G$1006,$G22)) | O22: =IF($G22="","",INDEX(BASE_PRODUTOS!$H$2:$H$1006,$G22)) | P22: =IF($G22="","",INDEX(BASE_PRODUTOS!$I$2:$I$1006,$G22)) | Q22: =IF($G22="","",INDEX(BASE_PRODUTOS!$J$2:$J$1006,$G22)) | R22: =IF($G22="","",INDEX(BASE_PRODUTOS!$M$2:$M$1006,$G22)) | S22: =IF($G22="","",INDEX(BASE_PRODUTOS!$N$2:$N$1006,$G22)) | T22: =IF($G22="","",INDEX(BASE_PRODUTOS!$D$2:$D$1006,$G22))
A23: 14 | D23: =IFERROR(VLOOKUP(B23,LISTAS!$A:$C,2,FALSE()),"") | E23: =IFERROR(VLOOKUP(B23,LISTAS!$A:$C,3,FALSE()),0) -> 0 | F23: =IFERROR(C23*E23,0) -> 0 | G23: =IFERROR(_xludf.aggregate(15,6,(ROW(BASE_PRODUTOS!$L$2:$L$1006)-ROW(BASE_PRODUTOS!$L$2)+1)/(BASE_PRODUTOS!$L$2:$L$1006>0),ROWS($G$10:G23)),"") | H23: =IF($G23="","",INDEX(BASE_PRODUTOS!$B$2:$B$1006,$G23)) | I23: =IF($G23="","",INDEX(BASE_PRODUTOS!$L$2:$L$1006,$G23)) | J23: =IF($G23="","",INDEX(BASE_PRODUTOS!$A$2:$A$1006,$G23)) | K23: =IF($G23="","",INDEX(BASE_PRODUTOS!$C$2:$C$1006,$G23)) | L23: =IF($G23="","",INDEX(BASE_PRODUTOS!$E$2:$E$1006,$G23)) | M23: =IF($G23="","",INDEX(BASE_PRODUTOS!$F$2:$F$1006,$G23)) | N23: =IF($G23="","",INDEX(BASE_PRODUTOS!$G$2:$G$1006,$G23)) | O23: =IF($G23="","",INDEX(BASE_PRODUTOS!$H$2:$H$1006,$G23)) | P23: =IF($G23="","",INDEX(BASE_PRODUTOS!$I$2:$I$1006,$G23)) | Q23: =IF($G23="","",INDEX(BASE_PRODUTOS!$J$2:$J$1006,$G23)) | R23: =IF($G23="","",INDEX(BASE_PRODUTOS!$M$2:$M$1006,$G23)) | S23: =IF($G23="","",INDEX(BASE_PRODUTOS!$N$2:$N$1006,$G23)) | T23: =IF($G23="","",INDEX(BASE_PRODUTOS!$D$2:$D$1006,$G23)) | V23: TOTAL DO LOTE | X23: =SUM(X10:X21) -> 0 | Y23: =SUM(Y10:Y21) -> 0 | AD23: =SUM(AD10:AD21) -> 0
A24: 15 | D24: =IFERROR(VLOOKUP(B24,LISTAS!$A:$C,2,FALSE()),"") | E24: =IFERROR(VLOOKUP(B24,LISTAS!$A:$C,3,FALSE()),0) -> 0 | F24: =IFERROR(C24*E24,0) -> 0 | G24: =IFERROR(_xludf.aggregate(15,6,(ROW(BASE_PRODUTOS!$L$2:$L$1006)-ROW(BASE_PRODUTOS!$L$2)+1)/(BASE_PRODUTOS!$L$2:$L$1006>0),ROWS($G$10:G24)),"") | H24: =IF($G24="","",INDEX(BASE_PRODUTOS!$B$2:$B$1006,$G24)) | I24: =IF($G24="","",INDEX(BASE_PRODUTOS!$L$2:$L$1006,$G24)) | J24: =IF($G24="","",INDEX(BASE_PRODUTOS!$A$2:$A$1006,$G24)) | K24: =IF($G24="","",INDEX(BASE_PRODUTOS!$C$2:$C$1006,$G24)) | L24: =IF($G24="","",INDEX(BASE_PRODUTOS!$E$2:$E$1006,$G24)) | M24: =IF($G24="","",INDEX(BASE_PRODUTOS!$F$2:$F$1006,$G24)) | N24: =IF($G24="","",INDEX(BASE_PRODUTOS!$G$2:$G$1006,$G24)) | O24: =IF($G24="","",INDEX(BASE_PRODUTOS!$H$2:$H$1006,$G24)) | P24: =IF($G24="","",INDEX(BASE_PRODUTOS!$I$2:$I$1006,$G24)) | Q24: =IF($G24="","",INDEX(BASE_PRODUTOS!$J$2:$J$1006,$G24)) | R24: =IF($G24="","",INDEX(BASE_PRODUTOS!$M$2:$M$1006,$G24)) | S24: =IF($G24="","",INDEX(BASE_PRODUTOS!$N$2:$N$1006,$G24)) | T24: =IF($G24="","",INDEX(BASE_PRODUTOS!$D$2:$D$1006,$G24))
A25: 16 | D25: =IFERROR(VLOOKUP(B25,LISTAS!$A:$C,2,FALSE()),"") | E25: =IFERROR(VLOOKUP(B25,LISTAS!$A:$C,3,FALSE()),0) -> 0 | F25: =IFERROR(C25*E25,0) -> 0 | G25: =IFERROR(_xludf.aggregate(15,6,(ROW(BASE_PRODUTOS!$L$2:$L$1006)-ROW(BASE_PRODUTOS!$L$2)+1)/(BASE_PRODUTOS!$L$2:$L$1006>0),ROWS($G$10:G25)),"") | H25: =IF($G25="","",INDEX(BASE_PRODUTOS!$B$2:$B$1006,$G25)) | I25: =IF($G25="","",INDEX(BASE_PRODUTOS!$L$2:$L$1006,$G25)) | J25: =IF($G25="","",INDEX(BASE_PRODUTOS!$A$2:$A$1006,$G25)) | K25: =IF($G25="","",INDEX(BASE_PRODUTOS!$C$2:$C$1006,$G25)) | L25: =IF($G25="","",INDEX(BASE_PRODUTOS!$E$2:$E$1006,$G25)) | M25: =IF($G25="","",INDEX(BASE_PRODUTOS!$F$2:$F$1006,$G25)) | N25: =IF($G25="","",INDEX(BASE_PRODUTOS!$G$2:$G$1006,$G25)) | O25: =IF($G25="","",INDEX(BASE_PRODUTOS!$H$2:$H$1006,$G25)) | P25: =IF($G25="","",INDEX(BASE_PRODUTOS!$I$2:$I$1006,$G25)) | Q25: =IF($G25="","",INDEX(BASE_PRODUTOS!$J$2:$J$1006,$G25)) | R25: =IF($G25="","",INDEX(BASE_PRODUTOS!$M$2:$M$1006,$G25)) | S25: =IF($G25="","",INDEX(BASE_PRODUTOS!$N$2:$N$1006,$G25)) | T25: =IF($G25="","",INDEX(BASE_PRODUTOS!$D$2:$D$1006,$G25))
A26: 17 | D26: =IFERROR(VLOOKUP(B26,LISTAS!$A:$C,2,FALSE()),"") | E26: =IFERROR(VLOOKUP(B26,LISTAS!$A:$C,3,FALSE()),0) -> 0 | F26: =IFERROR(C26*E26,0) -> 0 | G26: =IFERROR(_xludf.aggregate(15,6,(ROW(BASE_PRODUTOS!$L$2:$L$1006)-ROW(BASE_PRODUTOS!$L$2)+1)/(BASE_PRODUTOS!$L$2:$L$1006>0),ROWS($G$10:G26)),"") | H26: =IF($G26="","",INDEX(BASE_PRODUTOS!$B$2:$B$1006,$G26)) | I26: =IF($G26="","",INDEX(BASE_PRODUTOS!$L$2:$L$1006,$G26)) | J26: =IF($G26="","",INDEX(BASE_PRODUTOS!$A$2:$A$1006,$G26)) | K26: =IF($G26="","",INDEX(BASE_PRODUTOS!$C$2:$C$1006,$G26)) | L26: =IF($G26="","",INDEX(BASE_PRODUTOS!$E$2:$E$1006,$G26)) | M26: =IF($G26="","",INDEX(BASE_PRODUTOS!$F$2:$F$1006,$G26)) | N26: =IF($G26="","",INDEX(BASE_PRODUTOS!$G$2:$G$1006,$G26)) | O26: =IF($G26="","",INDEX(BASE_PRODUTOS!$H$2:$H$1006,$G26)) | P26: =IF($G26="","",INDEX(BASE_PRODUTOS!$I$2:$I$1006,$G26)) | Q26: =IF($G26="","",INDEX(BASE_PRODUTOS!$J$2:$J$1006,$G26)) | R26: =IF($G26="","",INDEX(BASE_PRODUTOS!$M$2:$M$1006,$G26)) | S26: =IF($G26="","",INDEX(BASE_PRODUTOS!$N$2:$N$1006,$G26)) | T26: =IF($G26="","",INDEX(BASE_PRODUTOS!$D$2:$D$1006,$G26))
A27: 18 | D27: =IFERROR(VLOOKUP(B27,LISTAS!$A:$C,2,FALSE()),"") | E27: =IFERROR(VLOOKUP(B27,LISTAS!$A:$C,3,FALSE()),0) -> 0 | F27: =IFERROR(C27*E27,0) -> 0 | G27: =IFERROR(_xludf.aggregate(15,6,(ROW(BASE_PRODUTOS!$L$2:$L$1006)-ROW(BASE_PRODUTOS!$L$2)+1)/(BASE_PRODUTOS!$L$2:$L$1006>0),ROWS($G$10:G27)),"") | H27: =IF($G27="","",INDEX(BASE_PRODUTOS!$B$2:$B$1006,$G27)) | I27: =IF($G27="","",INDEX(BASE_PRODUTOS!$L$2:$L$1006,$G27)) | J27: =IF($G27="","",INDEX(BASE_PRODUTOS!$A$2:$A$1006,$G27)) | K27: =IF($G27="","",INDEX(BASE_PRODUTOS!$C$2:$C$1006,$G27)) | L27: =IF($G27="","",INDEX(BASE_PRODUTOS!$E$2:$E$1006,$G27)) | M27: =IF($G27="","",INDEX(BASE_PRODUTOS!$F$2:$F$1006,$G27)) | N27: =IF($G27="","",INDEX(BASE_PRODUTOS!$G$2:$G$1006,$G27)) | O27: =IF($G27="","",INDEX(BASE_PRODUTOS!$H$2:$H$1006,$G27)) | P27: =IF($G27="","",INDEX(BASE_PRODUTOS!$I$2:$I$1006,$G27)) | Q27: =IF($G27="","",INDEX(BASE_PRODUTOS!$J$2:$J$1006,$G27)) | R27: =IF($G27="","",INDEX(BASE_PRODUTOS!$M$2:$M$1006,$G27)) | S27: =IF($G27="","",INDEX(BASE_PRODUTOS!$N$2:$N$1006,$G27)) | T27: =IF($G27="","",INDEX(BASE_PRODUTOS!$D$2:$D$1006,$G27))
A28: 19 | D28: =IFERROR(VLOOKUP(B28,LISTAS!$A:$C,2,FALSE()),"") | E28: =IFERROR(VLOOKUP(B28,LISTAS!$A:$C,3,FALSE()),0) -> 0 | F28: =IFERROR(C28*E28,0) -> 0 | G28: =IFERROR(_xludf.aggregate(15,6,(ROW(BASE_PRODUTOS!$L$2:$L$1006)-ROW(BASE_PRODUTOS!$L$2)+1)/(BASE_PRODUTOS!$L$2:$L$1006>0),ROWS($G$10:G28)),"") | H28: =IF($G28="","",INDEX(BASE_PRODUTOS!$B$2:$B$1006,$G28)) | I28: =IF($G28="","",INDEX(BASE_PRODUTOS!$L$2:$L$1006,$G28)) | J28: =IF($G28="","",INDEX(BASE_PRODUTOS!$A$2:$A$1006,$G28)) | K28: =IF($G28="","",INDEX(BASE_PRODUTOS!$C$2:$C$1006,$G28)) | L28: =IF($G28="","",INDEX(BASE_PRODUTOS!$E$2:$E$1006,$G28)) | M28: =IF($G28="","",INDEX(BASE_PRODUTOS!$F$2:$F$1006,$G28)) | N28: =IF($G28="","",INDEX(BASE_PRODUTOS!$G$2:$G$1006,$G28)) | O28: =IF($G28="","",INDEX(BASE_PRODUTOS!$H$2:$H$1006,$G28)) | P28: =IF($G28="","",INDEX(BASE_PRODUTOS!$I$2:$I$1006,$G28)) | Q28: =IF($G28="","",INDEX(BASE_PRODUTOS!$J$2:$J$1006,$G28)) | R28: =IF($G28="","",INDEX(BASE_PRODUTOS!$M$2:$M$1006,$G28)) | S28: =IF($G28="","",INDEX(BASE_PRODUTOS!$N$2:$N$1006,$G28)) | T28: =IF($G28="","",INDEX(BASE_PRODUTOS!$D$2:$D$1006,$G28))
A29: 20 | D29: =IFERROR(VLOOKUP(B29,LISTAS!$A:$C,2,FALSE()),"") | E29: =IFERROR(VLOOKUP(B29,LISTAS!$A:$C,3,FALSE()),0) -> 0 | F29: =IFERROR(C29*E29,0) -> 0 | G29: =IFERROR(_xludf.aggregate(15,6,(ROW(BASE_PRODUTOS!$L$2:$L$1006)-ROW(BASE_PRODUTOS!$L$2)+1)/(BASE_PRODUTOS!$L$2:$L$1006>0),ROWS($G$10:G29)),"") | H29: =IF($G29="","",INDEX(BASE_PRODUTOS!$B$2:$B$1006,$G29)) | I29: =IF($G29="","",INDEX(BASE_PRODUTOS!$L$2:$L$1006,$G29)) | J29: =IF($G29="","",INDEX(BASE_PRODUTOS!$A$2:$A$1006,$G29)) | K29: =IF($G29="","",INDEX(BASE_PRODUTOS!$C$2:$C$1006,$G29)) | L29: =IF($G29="","",INDEX(BASE_PRODUTOS!$E$2:$E$1006,$G29)) | M29: =IF($G29="","",INDEX(BASE_PRODUTOS!$F$2:$F$1006,$G29)) | N29: =IF($G29="","",INDEX(BASE_PRODUTOS!$G$2:$G$1006,$G29)) | O29: =IF($G29="","",INDEX(BASE_PRODUTOS!$H$2:$H$1006,$G29)) | P29: =IF($G29="","",INDEX(BASE_PRODUTOS!$I$2:$I$1006,$G29)) | Q29: =IF($G29="","",INDEX(BASE_PRODUTOS!$J$2:$J$1006,$G29)) | R29: =IF($G29="","",INDEX(BASE_PRODUTOS!$M$2:$M$1006,$G29)) | S29: =IF($G29="","",INDEX(BASE_PRODUTOS!$N$2:$N$1006,$G29)) | T29: =IF($G29="","",INDEX(BASE_PRODUTOS!$D$2:$D$1006,$G29))
A30: 21 | D30: =IFERROR(VLOOKUP(B30,LISTAS!$A:$C,2,FALSE()),"") | E30: =IFERROR(VLOOKUP(B30,LISTAS!$A:$C,3,FALSE()),0) -> 0 | F30: =IFERROR(C30*E30,0) -> 0 | G30: =IFERROR(_xludf.aggregate(15,6,(ROW(BASE_PRODUTOS!$L$2:$L$1006)-ROW(BASE_PRODUTOS!$L$2)+1)/(BASE_PRODUTOS!$L$2:$L$1006>0),ROWS($G$10:G30)),"") | H30: =IF($G30="","",INDEX(BASE_PRODUTOS!$B$2:$B$1006,$G30)) | I30: =IF($G30="","",INDEX(BASE_PRODUTOS!$L$2:$L$1006,$G30)) | J30: =IF($G30="","",INDEX(BASE_PRODUTOS!$A$2:$A$1006,$G30)) | K30: =IF($G30="","",INDEX(BASE_PRODUTOS!$C$2:$C$1006,$G30)) | L30: =IF($G30="","",INDEX(BASE_PRODUTOS!$E$2:$E$1006,$G30)) | M30: =IF($G30="","",INDEX(BASE_PRODUTOS!$F$2:$F$1006,$G30)) | N30: =IF($G30="","",INDEX(BASE_PRODUTOS!$G$2:$G$1006,$G30)) | O30: =IF($G30="","",INDEX(BASE_PRODUTOS!$H$2:$H$1006,$G30)) | P30: =IF($G30="","",INDEX(BASE_PRODUTOS!$I$2:$I$1006,$G30)) | Q30: =IF($G30="","",INDEX(BASE_PRODUTOS!$J$2:$J$1006,$G30)) | R30: =IF($G30="","",INDEX(BASE_PRODUTOS!$M$2:$M$1006,$G30)) | S30: =IF($G30="","",INDEX(BASE_PRODUTOS!$N$2:$N$1006,$G30)) | T30: =IF($G30="","",INDEX(BASE_PRODUTOS!$D$2:$D$1006,$G30))
A31: 22 | D31: =IFERROR(VLOOKUP(B31,LISTAS!$A:$C,2,FALSE()),"") | E31: =IFERROR(VLOOKUP(B31,LISTAS!$A:$C,3,FALSE()),0) -> 0 | F31: =IFERROR(C31*E31,0) -> 0 | G31: =IFERROR(_xludf.aggregate(15,6,(ROW(BASE_PRODUTOS!$L$2:$L$1006)-ROW(BASE_PRODUTOS!$L$2)+1)/(BASE_PRODUTOS!$L$2:$L$1006>0),ROWS($G$10:G31)),"") | H31: =IF($G31="","",INDEX(BASE_PRODUTOS!$B$2:$B$1006,$G31)) | I31: =IF($G31="","",INDEX(BASE_PRODUTOS!$L$2:$L$1006,$G31)) | J31: =IF($G31="","",INDEX(BASE_PRODUTOS!$A$2:$A$1006,$G31)) | K31: =IF($G31="","",INDEX(BASE_PRODUTOS!$C$2:$C$1006,$G31)) | L31: =IF($G31="","",INDEX(BASE_PRODUTOS!$E$2:$E$1006,$G31)) | M31: =IF($G31="","",INDEX(BASE_PRODUTOS!$F$2:$F$1006,$G31)) | N31: =IF($G31="","",INDEX(BASE_PRODUTOS!$G$2:$G$1006,$G31)) | O31: =IF($G31="","",INDEX(BASE_PRODUTOS!$H$2:$H$1006,$G31)) | P31: =IF($G31="","",INDEX(BASE_PRODUTOS!$I$2:$I$1006,$G31)) | Q31: =IF($G31="","",INDEX(BASE_PRODUTOS!$J$2:$J$1006,$G31)) | R31: =IF($G31="","",INDEX(BASE_PRODUTOS!$M$2:$M$1006,$G31)) | S31: =IF($G31="","",INDEX(BASE_PRODUTOS!$N$2:$N$1006,$G31)) | T31: =IF($G31="","",INDEX(BASE_PRODUTOS!$D$2:$D$1006,$G31))
A32: 23 | D32: =IFERROR(VLOOKUP(B32,LISTAS!$A:$C,2,FALSE()),"") | E32: =IFERROR(VLOOKUP(B32,LISTAS!$A:$C,3,FALSE()),0) -> 0 | F32: =IFERROR(C32*E32,0) -> 0 | G32: =IFERROR(_xludf.aggregate(15,6,(ROW(BASE_PRODUTOS!$L$2:$L$1006)-ROW(BASE_PRODUTOS!$L$2)+1)/(BASE_PRODUTOS!$L$2:$L$1006>0),ROWS($G$10:G32)),"") | H32: =IF($G32="","",INDEX(BASE_PRODUTOS!$B$2:$B$1006,$G32)) | I32: =IF($G32="","",INDEX(BASE_PRODUTOS!$L$2:$L$1006,$G32)) | J32: =IF($G32="","",INDEX(BASE_PRODUTOS!$A$2:$A$1006,$G32)) | K32: =IF($G32="","",INDEX(BASE_PRODUTOS!$C$2:$C$1006,$G32)) | L32: =IF($G32="","",INDEX(BASE_PRODUTOS!$E$2:$E$1006,$G32)) | M32: =IF($G32="","",INDEX(BASE_PRODUTOS!$F$2:$F$1006,$G32)) | N32: =IF($G32="","",INDEX(BASE_PRODUTOS!$G$2:$G$1006,$G32)) | O32: =IF($G32="","",INDEX(BASE_PRODUTOS!$H$2:$H$1006,$G32)) | P32: =IF($G32="","",INDEX(BASE_PRODUTOS!$I$2:$I$1006,$G32)) | Q32: =IF($G32="","",INDEX(BASE_PRODUTOS!$J$2:$J$1006,$G32)) | R32: =IF($G32="","",INDEX(BASE_PRODUTOS!$M$2:$M$1006,$G32)) | S32: =IF($G32="","",INDEX(BASE_PRODUTOS!$N$2:$N$1006,$G32)) | T32: =IF($G32="","",INDEX(BASE_PRODUTOS!$D$2:$D$1006,$G32))
A33: 24 | D33: =IFERROR(VLOOKUP(B33,LISTAS!$A:$C,2,FALSE()),"") | E33: =IFERROR(VLOOKUP(B33,LISTAS!$A:$C,3,FALSE()),0) -> 0 | F33: =IFERROR(C33*E33,0) -> 0 | G33: =IFERROR(_xludf.aggregate(15,6,(ROW(BASE_PRODUTOS!$L$2:$L$1006)-ROW(BASE_PRODUTOS!$L$2)+1)/(BASE_PRODUTOS!$L$2:$L$1006>0),ROWS($G$10:G33)),"") | H33: =IF($G33="","",INDEX(BASE_PRODUTOS!$B$2:$B$1006,$G33)) | I33: =IF($G33="","",INDEX(BASE_PRODUTOS!$L$2:$L$1006,$G33)) | J33: =IF($G33="","",INDEX(BASE_PRODUTOS!$A$2:$A$1006,$G33)) | K33: =IF($G33="","",INDEX(BASE_PRODUTOS!$C$2:$C$1006,$G33)) | L33: =IF($G33="","",INDEX(BASE_PRODUTOS!$E$2:$E$1006,$G33)) | M33: =IF($G33="","",INDEX(BASE_PRODUTOS!$F$2:$F$1006,$G33)) | N33: =IF($G33="","",INDEX(BASE_PRODUTOS!$G$2:$G$1006,$G33)) | O33: =IF($G33="","",INDEX(BASE_PRODUTOS!$H$2:$H$1006,$G33)) | P33: =IF($G33="","",INDEX(BASE_PRODUTOS!$I$2:$I$1006,$G33)) | Q33: =IF($G33="","",INDEX(BASE_PRODUTOS!$J$2:$J$1006,$G33)) | R33: =IF($G33="","",INDEX(BASE_PRODUTOS!$M$2:$M$1006,$G33)) | S33: =IF($G33="","",INDEX(BASE_PRODUTOS!$N$2:$N$1006,$G33)) | T33: =IF($G33="","",INDEX(BASE_PRODUTOS!$D$2:$D$1006,$G33))
A34: 25 | D34: =IFERROR(VLOOKUP(B34,LISTAS!$A:$C,2,FALSE()),"") | E34: =IFERROR(VLOOKUP(B34,LISTAS!$A:$C,3,FALSE()),0) -> 0 | F34: =IFERROR(C34*E34,0) -> 0 | G34: =IFERROR(_xludf.aggregate(15,6,(ROW(BASE_PRODUTOS!$L$2:$L$1006)-ROW(BASE_PRODUTOS!$L$2)+1)/(BASE_PRODUTOS!$L$2:$L$1006>0),ROWS($G$10:G34)),"") | H34: =IF($G34="","",INDEX(BASE_PRODUTOS!$B$2:$B$1006,$G34)) | I34: =IF($G34="","",INDEX(BASE_PRODUTOS!$L$2:$L$1006,$G34)) | J34: =IF($G34="","",INDEX(BASE_PRODUTOS!$A$2:$A$1006,$G34)) | K34: =IF($G34="","",INDEX(BASE_PRODUTOS!$C$2:$C$1006,$G34)) | L34: =IF($G34="","",INDEX(BASE_PRODUTOS!$E$2:$E$1006,$G34)) | M34: =IF($G34="","",INDEX(BASE_PRODUTOS!$F$2:$F$1006,$G34)) | N34: =IF($G34="","",INDEX(BASE_PRODUTOS!$G$2:$G$1006,$G34)) | O34: =IF($G34="","",INDEX(BASE_PRODUTOS!$H$2:$H$1006,$G34)) | P34: =IF($G34="","",INDEX(BASE_PRODUTOS!$I$2:$I$1006,$G34)) | Q34: =IF($G34="","",INDEX(BASE_PRODUTOS!$J$2:$J$1006,$G34)) | R34: =IF($G34="","",INDEX(BASE_PRODUTOS!$M$2:$M$1006,$G34)) | S34: =IF($G34="","",INDEX(BASE_PRODUTOS!$N$2:$N$1006,$G34)) | T34: =IF($G34="","",INDEX(BASE_PRODUTOS!$D$2:$D$1006,$G34))
A35: 26 | D35: =IFERROR(VLOOKUP(B35,LISTAS!$A:$C,2,FALSE()),"") | E35: =IFERROR(VLOOKUP(B35,LISTAS!$A:$C,3,FALSE()),0) -> 0 | F35: =IFERROR(C35*E35,0) -> 0 | G35: =IFERROR(_xludf.aggregate(15,6,(ROW(BASE_PRODUTOS!$L$2:$L$1006)-ROW(BASE_PRODUTOS!$L$2)+1)/(BASE_PRODUTOS!$L$2:$L$1006>0),ROWS($G$10:G35)),"") | H35: =IF($G35="","",INDEX(BASE_PRODUTOS!$B$2:$B$1006,$G35)) | I35: =IF($G35="","",INDEX(BASE_PRODUTOS!$L$2:$L$1006,$G35)) | J35: =IF($G35="","",INDEX(BASE_PRODUTOS!$A$2:$A$1006,$G35)) | K35: =IF($G35="","",INDEX(BASE_PRODUTOS!$C$2:$C$1006,$G35)) | L35: =IF($G35="","",INDEX(BASE_PRODUTOS!$E$2:$E$1006,$G35)) | M35: =IF($G35="","",INDEX(BASE_PRODUTOS!$F$2:$F$1006,$G35)) | N35: =IF($G35="","",INDEX(BASE_PRODUTOS!$G$2:$G$1006,$G35)) | O35: =IF($G35="","",INDEX(BASE_PRODUTOS!$H$2:$H$1006,$G35)) | P35: =IF($G35="","",INDEX(BASE_PRODUTOS!$I$2:$I$1006,$G35)) | Q35: =IF($G35="","",INDEX(BASE_PRODUTOS!$J$2:$J$1006,$G35)) | R35: =IF($G35="","",INDEX(BASE_PRODUTOS!$M$2:$M$1006,$G35)) | S35: =IF($G35="","",INDEX(BASE_PRODUTOS!$N$2:$N$1006,$G35)) | T35: =IF($G35="","",INDEX(BASE_PRODUTOS!$D$2:$D$1006,$G35))
... A59: 50 | D59: =IFERROR(VLOOKUP(B59,LISTAS!$A:$C,2,FALSE()),"") | E59: =IFERROR(VLOOKUP(B59,LISTAS!$A:$C,3,FALSE()),0) -> 0 | F59: =IFERROR(C59*E59,0) -> 0 | G59: =IFERROR(_xludf.aggregate(15,6,(ROW(BASE_PRODUTOS!$L$2:$L$1006)-ROW(BASE_PRODUTOS!$L$2)+1)/(BASE_PRODUTOS!$L$2:$L$1006>0),ROWS($G$10:G59)),"") | H59: =IF($G59="","",INDEX(BASE_PRODUTOS!$B$2:$B$1006,$G59)) | I59: =IF($G59="","",INDEX(BASE_PRODUTOS!$L$2:$L$1006,$G59)) | J59: =IF($G59="","",INDEX(BASE_PRODUTOS!$A$2:$A$1006,$G59)) | K59: =IF($G59="","",INDEX(BASE_PRODUTOS!$C$2:$C$1006,$G59)) | L59: =IF($G59="","",INDEX(BASE_PRODUTOS!$E$2:$E$1006,$G59)) | M59: =IF($G59="","",INDEX(BASE_PRODUTOS!$F$2:$F$1006,$G59)) | N59: =IF($G59="","",INDEX(BASE_PRODUTOS!$G$2:$G$1006,$G59)) | O59: =IF($G59="","",INDEX(BASE_PRODUTOS!$H$2:$H$1006,$G59)) | P59: =IF($G59="","",INDEX(BASE_PRODUTOS!$I$2:$I$1006,$G59)) | Q59: =IF($G59="","",INDEX(BASE_PRODUTOS!$J$2:$J$1006,$G59)) | R59: =IF($G59="","",INDEX(BASE_PRODUTOS!$M$2:$M$1006,$G59)) | S59: =IF($G59="","",INDEX(BASE_PRODUTOS!$N$2:$N$1006,$G59)) | T59: =IF($G59="","",INDEX(BASE_PRODUTOS!$D$2:$D$1006,$G59))
G60: =IFERROR(_xludf.aggregate(15,6,(ROW(BASE_PRODUTOS!$L$2:$L$1006)-ROW(BASE_PRODUTOS!$L$2)+1)/(BASE_PRODUTOS!$L$2:$L$1006>0),ROWS($G$10:G60)),"") | H60: =IF($G60="","",INDEX(BASE_PRODUTOS!$B$2:$B$1006,$G60)) | I60: =IF($G60="","",INDEX(BASE_PRODUTOS!$L$2:$L$1006,$G60)) | J60: =IF($G60="","",INDEX(BASE_PRODUTOS!$A$2:$A$1006,$G60)) | K60: =IF($G60="","",INDEX(BASE_PRODUTOS!$C$2:$C$1006,$G60)) | L60: =IF($G60="","",INDEX(BASE_PRODUTOS!$E$2:$E$1006,$G60)) | M60: =IF($G60="","",INDEX(BASE_PRODUTOS!$F$2:$F$1006,$G60)) | N60: =IF($G60="","",INDEX(BASE_PRODUTOS!$G$2:$G$1006,$G60)) | O60: =IF($G60="","",INDEX(BASE_PRODUTOS!$H$2:$H$1006,$G60)) | P60: =IF($G60="","",INDEX(BASE_PRODUTOS!$I$2:$I$1006,$G60)) | Q60: =IF($G60="","",INDEX(BASE_PRODUTOS!$J$2:$J$1006,$G60)) | R60: =IF($G60="","",INDEX(BASE_PRODUTOS!$M$2:$M$1006,$G60)) | S60: =IF($G60="","",INDEX(BASE_PRODUTOS!$N$2:$N$1006,$G60)) | T60: =IF($G60="","",INDEX(BASE_PRODUTOS!$D$2:$D$1006,$G60))
G61: =IFERROR(_xludf.aggregate(15,6,(ROW(BASE_PRODUTOS!$L$2:$L$1006)-ROW(BASE_PRODUTOS!$L$2)+1)/(BASE_PRODUTOS!$L$2:$L$1006>0),ROWS($G$10:G61)),"") | H61: =IF($G61="","",INDEX(BASE_PRODUTOS!$B$2:$B$1006,$G61)) | I61: =IF($G61="","",INDEX(BASE_PRODUTOS!$L$2:$L$1006,$G61)) | J61: =IF($G61="","",INDEX(BASE_PRODUTOS!$A$2:$A$1006,$G61)) | K61: =IF($G61="","",INDEX(BASE_PRODUTOS!$C$2:$C$1006,$G61)) | L61: =IF($G61="","",INDEX(BASE_PRODUTOS!$E$2:$E$1006,$G61)) | M61: =IF($G61="","",INDEX(BASE_PRODUTOS!$F$2:$F$1006,$G61)) | N61: =IF($G61="","",INDEX(BASE_PRODUTOS!$G$2:$G$1006,$G61)) | O61: =IF($G61="","",INDEX(BASE_PRODUTOS!$H$2:$H$1006,$G61)) | P61: =IF($G61="","",INDEX(BASE_PRODUTOS!$I$2:$I$1006,$G61)) | Q61: =IF($G61="","",INDEX(BASE_PRODUTOS!$J$2:$J$1006,$G61)) | R61: =IF($G61="","",INDEX(BASE_PRODUTOS!$M$2:$M$1006,$G61)) | S61: =IF($G61="","",INDEX(BASE_PRODUTOS!$N$2:$N$1006,$G61)) | T61: =IF($G61="","",INDEX(BASE_PRODUTOS!$D$2:$D$1006,$G61))
G62: =IFERROR(_xludf.aggregate(15,6,(ROW(BASE_PRODUTOS!$L$2:$L$1006)-ROW(BASE_PRODUTOS!$L$2)+1)/(BASE_PRODUTOS!$L$2:$L$1006>0),ROWS($G$10:G62)),"") | H62: =IF($G62="","",INDEX(BASE_PRODUTOS!$B$2:$B$1006,$G62)) | I62: =IF($G62="","",INDEX(BASE_PRODUTOS!$L$2:$L$1006,$G62)) | J62: =IF($G62="","",INDEX(BASE_PRODUTOS!$A$2:$A$1006,$G62)) | K62: =IF($G62="","",INDEX(BASE_PRODUTOS!$C$2:$C$1006,$G62)) | L62: =IF($G62="","",INDEX(BASE_PRODUTOS!$E$2:$E$1006,$G62)) | M62: =IF($G62="","",INDEX(BASE_PRODUTOS!$F$2:$F$1006,$G62)) | N62: =IF($G62="","",INDEX(BASE_PRODUTOS!$G$2:$G$1006,$G62)) | O62: =IF($G62="","",INDEX(BASE_PRODUTOS!$H$2:$H$1006,$G62)) | P62: =IF($G62="","",INDEX(BASE_PRODUTOS!$I$2:$I$1006,$G62)) | Q62: =IF($G62="","",INDEX(BASE_PRODUTOS!$J$2:$J$1006,$G62)) | R62: =IF($G62="","",INDEX(BASE_PRODUTOS!$M$2:$M$1006,$G62)) | S62: =IF($G62="","",INDEX(BASE_PRODUTOS!$N$2:$N$1006,$G62)) | T62: =IF($G62="","",INDEX(BASE_PRODUTOS!$D$2:$D$1006,$G62))
G63: =IFERROR(_xludf.aggregate(15,6,(ROW(BASE_PRODUTOS!$L$2:$L$1006)-ROW(BASE_PRODUTOS!$L$2)+1)/(BASE_PRODUTOS!$L$2:$L$1006>0),ROWS($G$10:G63)),"") | H63: =IF($G63="","",INDEX(BASE_PRODUTOS!$B$2:$B$1006,$G63)) | I63: =IF($G63="","",INDEX(BASE_PRODUTOS!$L$2:$L$1006,$G63)) | J63: =IF($G63="","",INDEX(BASE_PRODUTOS!$A$2:$A$1006,$G63)) | K63: =IF($G63="","",INDEX(BASE_PRODUTOS!$C$2:$C$1006,$G63)) | L63: =IF($G63="","",INDEX(BASE_PRODUTOS!$E$2:$E$1006,$G63)) | M63: =IF($G63="","",INDEX(BASE_PRODUTOS!$F$2:$F$1006,$G63)) | N63: =IF($G63="","",INDEX(BASE_PRODUTOS!$G$2:$G$1006,$G63)) | O63: =IF($G63="","",INDEX(BASE_PRODUTOS!$H$2:$H$1006,$G63)) | P63: =IF($G63="","",INDEX(BASE_PRODUTOS!$I$2:$I$1006,$G63)) | Q63: =IF($G63="","",INDEX(BASE_PRODUTOS!$J$2:$J$1006,$G63)) | R63: =IF($G63="","",INDEX(BASE_PRODUTOS!$M$2:$M$1006,$G63)) | S63: =IF($G63="","",INDEX(BASE_PRODUTOS!$N$2:$N$1006,$G63)) | T63: =IF($G63="","",INDEX(BASE_PRODUTOS!$D$2:$D$1006,$G63))
G64: =IFERROR(_xludf.aggregate(15,6,(ROW(BASE_PRODUTOS!$L$2:$L$1006)-ROW(BASE_PRODUTOS!$L$2)+1)/(BASE_PRODUTOS!$L$2:$L$1006>0),ROWS($G$10:G64)),"") | H64: =IF($G64="","",INDEX(BASE_PRODUTOS!$B$2:$B$1006,$G64)) | I64: =IF($G64="","",INDEX(BASE_PRODUTOS!$L$2:$L$1006,$G64)) | J64: =IF($G64="","",INDEX(BASE_PRODUTOS!$A$2:$A$1006,$G64)) | K64: =IF($G64="","",INDEX(BASE_PRODUTOS!$C$2:$C$1006,$G64)) | L64: =IF($G64="","",INDEX(BASE_PRODUTOS!$E$2:$E$1006,$G64)) | M64: =IF($G64="","",INDEX(BASE_PRODUTOS!$F$2:$F$1006,$G64)) | N64: =IF($G64="","",INDEX(BASE_PRODUTOS!$G$2:$G$1006,$G64)) | O64: =IF($G64="","",INDEX(BASE_PRODUTOS!$H$2:$H$1006,$G64)) | P64: =IF($G64="","",INDEX(BASE_PRODUTOS!$I$2:$I$1006,$G64)) | Q64: =IF($G64="","",INDEX(BASE_PRODUTOS!$J$2:$J$1006,$G64)) | R64: =IF($G64="","",INDEX(BASE_PRODUTOS!$M$2:$M$1006,$G64)) | S64: =IF($G64="","",INDEX(BASE_PRODUTOS!$N$2:$N$1006,$G64)) | T64: =IF($G64="","",INDEX(BASE_PRODUTOS!$D$2:$D$1006,$G64))
G65: =IFERROR(_xludf.aggregate(15,6,(ROW(BASE_PRODUTOS!$L$2:$L$1006)-ROW(BASE_PRODUTOS!$L$2)+1)/(BASE_PRODUTOS!$L$2:$L$1006>0),ROWS($G$10:G65)),"") | H65: =IF($G65="","",INDEX(BASE_PRODUTOS!$B$2:$B$1006,$G65)) | I65: =IF($G65="","",INDEX(BASE_PRODUTOS!$L$2:$L$1006,$G65)) | J65: =IF($G65="","",INDEX(BASE_PRODUTOS!$A$2:$A$1006,$G65)) | K65: =IF($G65="","",INDEX(BASE_PRODUTOS!$C$2:$C$1006,$G65)) | L65: =IF($G65="","",INDEX(BASE_PRODUTOS!$E$2:$E$1006,$G65)) | M65: =IF($G65="","",INDEX(BASE_PRODUTOS!$F$2:$F$1006,$G65)) | N65: =IF($G65="","",INDEX(BASE_PRODUTOS!$G$2:$G$1006,$G65)) | O65: =IF($G65="","",INDEX(BASE_PRODUTOS!$H$2:$H$1006,$G65)) | P65: =IF($G65="","",INDEX(BASE_PRODUTOS!$I$2:$I$1006,$G65)) | Q65: =IF($G65="","",INDEX(BASE_PRODUTOS!$J$2:$J$1006,$G65)) | R65: =IF($G65="","",INDEX(BASE_PRODUTOS!$M$2:$M$1006,$G65)) | S65: =IF($G65="","",INDEX(BASE_PRODUTOS!$N$2:$N$1006,$G65)) | T65: =IF($G65="","",INDEX(BASE_PRODUTOS!$D$2:$D$1006,$G65))
...

Sheet BASE_PRODUTOS
A1: Código | B1: Produto Agrupado | C1: Peça | D1: Produto Original | E1: Comprimento (m) | F1: Largura (m) | G1: Espessura (mm) | H1: Material | I1: Tipo Chapa | J1: Qtde peça/produto | K1: m² peça unit. | L1: Qtde produto no lote | M1: Qtde peças no lote | N1: m² no lote | O1: Descr.Familia | P1: Produto extraído antes do agrupamento
A2: 30006101 | B2: CADEIRA SANTIAGO | C2: PE TRAS 880X30(911)X25 MDF (13PC) ESQ SANTIAGO | D2: PE TRAS 880X30(911)X25 MDF (13PC) ESQ SANTIAGO | E2: 0.88 | F2: 0.03 | G2: 25 | H2: MDF | I2: MDF 25mm | J2: 1 | K2: =IFERROR(E2*F2,0)*J2 -> 0.0264 | L2: =IFERROR(SUMIF(CALCULO_LOTE!$B$10:$B$59,B2,CALCULO_LOTE!$C$10:$C$59),0) -> 0 | M2: =IFERROR(L2*J2,0) -> 0 | N2: =IFERROR(M2*K2,0) -> 0 | O2: PEÇAS | P2: CADEIRA SANTIAGO
A3: 30006102 | B3: CADEIRA SANTIAGO | C3: PE TRAS 880X30(911)X25 MDF (13PC) DIR SANTIAGO | D3: PE TRAS 880X30(911)X25 MDF (13PC) DIR SANTIAGO | E3: 0.88 | F3: 0.03 | G3: 25 | H3: MDF | I3: MDF 25mm | J3: 1 | K3: =IFERROR(E3*F3,0)*J3 -> 0.0264 | L3: =IFERROR(SUMIF(CALCULO_LOTE!$B$10:$B$59,B3,CALCULO_LOTE!$C$10:$C$59),0) -> 0 | M3: =IFERROR(L3*J3,0) -> 0 | N3: =IFERROR(M3*K3,0) -> 0 | O3: PEÇAS | P3: CADEIRA SANTIAGO
A4: 30006110 | B4: CADEIRA SANTIAGO | C4: PE FRONTAL 430X(108)51X25 MDF (DIR) SANTIAGO | D4: PE FRONTAL 430X(108)51X25 MDF (DIR) SANTIAGO | E4: 0.43 | F4: 0.051 | G4: 25 | H4: MDF | I4: MDF 25mm | J4: 1 | K4: =IFERROR(E4*F4,0)*J4 -> 0.02193 | L4: =IFERROR(SUMIF(CALCULO_LOTE!$B$10:$B$59,B4,CALCULO_LOTE!$C$10:$C$59),0) -> 0 | M4: =IFERROR(L4*J4,0) -> 0 | N4: =IFERROR(M4*K4,0) -> 0 | O4: PEÇAS | P4: CADEIRA SANTIAGO
A5: 30003405 | B5: CADEIRA SANTIAGO | C5: TRAVESSA ASSENTO 360X70X18 MDF | D5: TRAVESSA ASSENTO 360X70X18 MDF | E5: 0.36 | F5: 0.07 | G5: 18 | H5: MDF | I5: MDF 18mm | J5: 2 | K5: =IFERROR(E5*F5,0)*J5 -> 0.0504 | L5: =IFERROR(SUMIF(CALCULO_LOTE!$B$10:$B$59,B5,CALCULO_LOTE!$C$10:$C$59),0) -> 0 | M5: =IFERROR(L5*J5,0) -> 0 | N5: =IFERROR(M5*K5,0) -> 0 | P5: CADEIRA SANTIAGO
A6: 30006103 | B6: CADEIRA SANTIAGO | C6: TRAVESSA LATERAL 340X70X18 MDF | D6: TRAVESSA LATERAL 340X70X18 MDF | E6: 0.34 | F6: 0.07 | G6: 18 | H6: MDF | I6: MDF 18mm | J6: 2 | K6: =IFERROR(E6*F6,0)*J6 -> 0.0476 | L6: =IFERROR(SUMIF(CALCULO_LOTE!$B$10:$B$59,B6,CALCULO_LOTE!$C$10:$C$59),0) -> 0 | M6: =IFERROR(L6*J6,0) -> 0 | N6: =IFERROR(M6*K6,0) -> 0 | P6: CADEIRA SANTIAGO
A7: 30006104 | B7: CADEIRA SANTIAGO | C7: MOLDURA ENCOSTO 445X280X15 MDF | D7: MOLDURA ENCOSTO 445X280X15 MDF | E7: 0.445 | F7: 0.28 | G7: 15 | H7: MDF | I7: MDF 15mm | J7: 1 | K7: =IFERROR(E7*F7,0)*J7 -> 0.1246 | L7: =IFERROR(SUMIF(CALCULO_LOTE!$B$10:$B$59,B7,CALCULO_LOTE!$C$10:$C$59),0) -> 0 | M7: =IFERROR(L7*J7,0) -> 0 | N7: =IFERROR(M7*K7,0) -> 0 | P7: CADEIRA SANTIAGO
A8: 30006111 | B8: CADEIRA SANTIAGO | C8: PE FRONTAL 430X(108)51X25 MDF (DIR) SANTIAGO | D8: PE FRONTAL 430X(108)51X25 MDF (DIR) SANTIAGO | E8: 0.43 | F8: 0.51 | G8: 25 | H8: MDF | I8: MDF 25mm | J8: 1 | K8: =IFERROR(E8*F8,0)*J8 -> 0.2193 | L8: =IFERROR(SUMIF(CALCULO_LOTE!$B$10:$B$59,B8,CALCULO_LOTE!$C$10:$C$59),0) -> 0 | M8: =IFERROR(L8*J8,0) -> 0 | N8: =IFERROR(M8*K8,0) -> 0 | O8: PEÇAS | P8: CADEIRA SANTIAGO
A9: 30001204 | B9: CADEIRA PÉ INTEIRO | C9: ASSENTO 430X403X09 MDP CAD PE INTEIRO/ MADEIRA | D9: ASSENTO 430X403X09 MDP CAD PE INTEIRO/ MADEIRA | E9: 0.43 | F9: 0.403 | G9: 9 | H9: MDP | I9: MDP 9mm | J9: 1 | K9: =IFERROR(E9*F9,0)*J9 -> 0.17329 | L9: =IFERROR(SUMIF(CALCULO_LOTE!$B$10:$B$59,B9,CALCULO_LOTE!$C$10:$C$59),0) -> 0 | M9: =IFERROR(L9*J9,0) -> 0 | N9: =IFERROR(M9*K9,0) -> 0 | P9: CADEIRA PÉ INTEIRO
A10: 30001203 | B10: CADEIRA PÉ INTEIRO | C10: LAT ASSENTO 430X80X18 MDF CAD PE INTEIRO | D10: LAT ASSENTO 430X80X18 MDF CAD PE INTEIRO | E10: 0.43 | F10: 0.08 | G10: 18 | H10: MDF | I10: MDF 18mm | J10: 2 | K10: =IFERROR(E10*F10,0)*J10 -> 0.0688 | L10: =IFERROR(SUMIF(CALCULO_LOTE!$B$10:$B$59,B10,CALCULO_LOTE!$C$10:$C$59),0) -> 0 | M10: =IFERROR(L10*J10,0) -> 0 | N10: =IFERROR(M10*K10,0) -> 0 | P10: CADEIRA PÉ INTEIRO
A11: 30001205 | B11: CADEIRA PÉ INTEIRO | C11: TRAV ASSENTO 367X80X15 MDP CAD PE INTEIRO | D11: TRAV ASSENTO 367X80X15 MDP CAD PE INTEIRO | E11: 0.367 | F11: 0.08 | G11: 15 | H11: MDP | I11: MDP 15mm | J11: 1 | K11: =IFERROR(E11*F11,0)*J11 -> 0.02936 | L11: =IFERROR(SUMIF(CALCULO_LOTE!$B$10:$B$59,B11,CALCULO_LOTE!$C$10:$C$59),0) -> 0 | M11: =IFERROR(L11*J11,0) -> 0 | N11: =IFERROR(M11*K11,0) -> 0 | P11: CADEIRA PÉ INTEIRO
A12: 30001202 | B12: CADEIRA PÉ INTEIRO | C12: PÉ FRONTAL 441X65(911)X25 MDF (16PÇS) - CAD PÉ | D12: PÉ FRONTAL 441X65(911)X25 MDF (16PÇS) - CAD PÉ | E12: 0.441 | F12: 0.065 | G12: 25 | H12: MDF | I12: MDF 25mm | J12: 2 | K12: =IFERROR(E12*F12,0)*J12 -> 0.05733 | L12: =IFERROR(SUMIF(CALCULO_LOTE!$B$10:$B$59,B12,CALCULO_LOTE!$C$10:$C$59),0) -> 0 | M12: =IFERROR(L12*J12,0) -> 0 | N12: =IFERROR(M12*K12,0) -> 0 | P12: CADEIRA PÉ INTEIRO
A13: 30001206 | B13: CADEIRA PÉ INTEIRO | C13: TRAVESSA ENCOSTO 360X80X15 MDP CAD PE INTEIRO | D13: TRAVESSA ENCOSTO 360X80X15 MDP CAD PE INTEIRO | E13: 0.36 | F13: 0.08 | G13: 15 | H13: MDP | I13: MDP 15mm | J13: 1 | K13: =IFERROR(E13*F13,0)*J13 -> 0.0288 | L13: =IFERROR(SUMIF(CALCULO_LOTE!$B$10:$B$59,B13,CALCULO_LOTE!$C$10:$C$59),0) -> 0 | M13: =IFERROR(L13*J13,0) -> 0 | N13: =IFERROR(M13*K13,0) -> 0 | P13: CADEIRA PÉ INTEIRO
A14: 30001207 | B14: CADEIRA PÉ INTEIRO | C14: TRAVESSA 360X62X15 MDP CAD PE INTEIRO | D14: TRAVESSA 360X62X15 MDP CAD PE INTEIRO | E14: 0.36 | F14: 0.062 | G14: 15 | H14: MDP | I14: MDP 15mm | J14: 1 | K14: =IFERROR(E14*F14,0)*J14 -> 0.02232 | L14: =IFERROR(SUMIF(CALCULO_LOTE!$B$10:$B$59,B14,CALCULO_LOTE!$C$10:$C$59),0) -> 0 | M14: =IFERROR(L14*J14,0) -> 0 | N14: =IFERROR(M14*K14,0) -> 0 | P14: CADEIRA PÉ INTEIRO
A15: 30001308 | B15: CADEIRA PÉ INTEIRO | C15: APOIO ESPALDAR 360X40X25 MDP - PE INTEIRO | D15: APOIO ESPALDAR 360X40X25 MDP - PE INTEIRO | E15: 0.36 | F15: 0.04 | G15: 25 | H15: MDP | I15: MDP 25mm | J15: 1 | K15: =IFERROR(E15*F15,0)*J15 -> 0.0144 | L15: =IFERROR(SUMIF(CALCULO_LOTE!$B$10:$B$59,B15,CALCULO_LOTE!$C$10:$C$59),0) -> 0 | M15: =IFERROR(L15*J15,0) -> 0 | N15: =IFERROR(M15*K15,0) -> 0 | P15: CADEIRA PÉ INTEIRO
A16: 30001309 | B16: CADEIRA PÉ INTEIRO | C16: TRA CENTR 360X56(911)X25 MDP (14PCS) - PE INTEIRO | D16: TRA CENTR 360X56(911)X25 MDP (14PCS) - PE INTEIRO | E16: 0.36 | F16: 0.056 | G16: 25 | H16: MDP | I16: MDP 25mm | J16: 1 | K16: =IFERROR(E16*F16,0)*J16 -> 0.02016 | L16: =IFERROR(SUMIF(CALCULO_LOTE!$B$10:$B$59,B16,CALCULO_LOTE!$C$10:$C$59),0) -> 0 | M16: =IFERROR(L16*J16,0) -> 0 | N16: =IFERROR(M16*K16,0) -> 0 | P16: CADEIRA PÉ INTEIRO
A17: 30001301 | B17: CADEIRA PÉ INTEIRO | C17: PE TRASEIRO 920X65(911)X25 MDF (11PCS)- CAD PE IN | D17: PE TRASEIRO 920X65(911)X25 MDF (11PCS)- CAD PE IN | E17: 0.92 | F17: 0.065 | G17: 25 | H17: MDF | I17: MDF 25mm | J17: 2 | K17: =IFERROR(E17*F17,0)*J17 -> 0.1196 | L17: =IFERROR(SUMIF(CALCULO_LOTE!$B$10:$B$59,B17,CALCULO_LOTE!$C$10:$C$59),0) -> 0 | M17: =IFERROR(L17*J17,0) -> 0 | N17: =IFERROR(M17*K17,0) -> 0 | P17: CADEIRA PÉ INTEIRO
A18: 20013102 | B18: MESA MIAMI 160 | C18: (10)PE MAIOR 760X100 (170) X15 MDF-MIAMI 1,37X0,80 | D18: (10)PE MAIOR 760X100 (170) X15 MDF-MIAMI 1,37X0,80 | E18: 0.76 | F18: 0.1 | G18: 15 | H18: MDF | I18: MDF 15mm | J18: 4 | K18: =IFERROR(E18*F18,0)*J18 -> 0.304 | L18: =IFERROR(SUMIF(CALCULO_LOTE!$B$10:$B$59,B18,CALCULO_LOTE!$C$10:$C$59),0) -> 0 | M18: =IFERROR(L18*J18,0) -> 0 | N18: =IFERROR(M18*K18,0) -> 0 | P18: MESA MIAMI 160
A19: 20013103 | B19: MESA MIAMI 160 | C19: (4) PE MENOR 760X85 (135) X15 MDF-MIAMI 1,37X0,80 | D19: (4) PE MENOR 760X85 (135) X15 MDF-MIAMI 1,37X0,80 | E19: 0.76 | F19: 0.85 | G19: 15 | H19: MDF | I19: MDF 15mm | J19: 4 | K19: =IFERROR(E19*F19,0)*J19 -> 2.584 | L19: =IFERROR(SUMIF(CALCULO_LOTE!$B$10:$B$59,B19,CALCULO_LOTE!$C$10:$C$59),0) -> 0 | M19: =IFERROR(L19*J19,0) -> 0 | N19: =IFERROR(M19*K19,0) -> 0 | P19: MESA MIAMI 160
A20: 20013107 | B20: MESA MIAMI 160 | C20: (3) TRAV.MENOR 610X100X15 MDP-MESA MIAMI 1,37X0, | D20: (3) TRAV.MENOR 610X100X15 MDP-MESA MIAMI 1,37X0, | E20: 0.61 | F20: 0.1 | G20: 15 | H20: MDP | I20: MDP 15mm | J20: 2 | K20: =IFERROR(E20*F20,0)*J20 -> 0.122 | L20: =IFERROR(SUMIF(CALCULO_LOTE!$B$10:$B$59,B20,CALCULO_LOTE!$C$10:$C$59),0) -> 0 | M20: =IFERROR(L20*J20,0) -> 0 | N20: =IFERROR(M20*K20,0) -> 0 | P20: MESA MIAMI 160
A21: 20014205 | B21: MESA MIAMI 160 | C21: (1) TAMPO 1602X802X12 MDP - MESA DAKAR/MIAMI 1,60 | D21: (1) TAMPO 1602X802X12 MDP - MESA DAKAR/MIAMI 1,60 | E21: 1.602 | F21: 0.802 | G21: 12 | H21: MDP | I21: MDP 12mm | J21: 1 | K21: =IFERROR(E21*F21,0)*J21 -> 1.284804 | L21: =IFERROR(SUMIF(CALCULO_LOTE!$B$10:$B$59,B21,CALCULO_LOTE!$C$10:$C$59),0) -> 0 | M21: =IFERROR(L21*J21,0) -> 0 | N21: =IFERROR(M21*K21,0) -> 0 | P21: MESA MIAMI 160
... A31: 20013107 | B31: MESA MIAMI 120 | C31: RAV.MENOR 610X100X15 MDP-MESA MIAM | D31: RAV.MENOR 610X100X15 MDP-MESA MIAM | E31: 0.61 | F31: 0.1 | G31: 15 | H31: MDP | I31: MDP 15mm | J31: 2 | K31: =IFERROR(E31*F31,0)*J31 -> 0.122 | L31: =IFERROR(SUMIF(CALCULO_LOTE!$B$10:$B$59,B31,CALCULO_LOTE!$C$10:$C$59),0) -> 0 | M31: =IFERROR(L31*J31,0) -> 0 | N31: =IFERROR(M31*K31,0) -> 0 | P31: MESA MIAMI 120
A32: 30076001 | B32: TAMPO C/ MOLDURA 1,60 X 0,90 - AMSTERDAM | C32: TRAV. MAIOR 1420X65X18 MDF - MESA AMST. 1,60X0,90 | D32: TRAV. MAIOR 1420X65X18 MDF - MESA AMST. 1,60X0,90 | E32: 1.42 | F32: 0.065 | G32: 18 | H32: MDF | I32: MDF 18mm | J32: 2 | K32: =IFERROR(E32*F32,0)*J32 -> 0.1846 | P32: TAMPO C/ MOLDURA 1,60 X 0,90 - AMSTERDAM
A33: 30076002 | B33: TAMPO C/ MOLDURA 1,60 X 0,90 - AMSTERDAM | C33: TRAV. MENOR 860X65 (135) X18 MDF - AMST. 1,60X0,90 | D33: TRAV. MENOR 860X65 (135) X18 MDF - AMST. 1,60X0,90 | E33: 0.86 | F33: 0.065 | G33: 18 | H33: MDF | I33: MDF 18mm | J33: 2 | K33: =IFERROR(E33*F33,0)*J33 -> 0.1118 | P33: TAMPO C/ MOLDURA 1,60 X 0,90 - AMSTERDAM
A34: 30076007 | B34: TAMPO C/ MOLDURA 1,60 X 0,90 - AMSTERDAM | C34: MOLDURA 1600X900 MDF12MM MESA AMST. 1,60X0,90 | D34: MOLDURA 1600X900 MDF12MM MESA AMST. 1,60X0,90 | E34: 1.6 | F34: 0.9 | G34: 12 | H34: MDF | I34: MDF 12mm | J34: 2 | K34: =IFERROR(E34*F34,0)*J34 -> 2.88 | P34: TAMPO C/ MOLDURA 1,60 X 0,90 - AMSTERDAM
A35: 30076008 | B35: TAMPO C/ MOLDURA 1,60 X 0,90 - AMSTERDAM | C35: TAMPO 1600X900 MDF 15MM MESA AMST. 1,60X0,90 | D35: TAMPO 1600X900 MDF 15MM MESA AMST. 1,60X0,90 | E35: 1.6 | F35: 0.9 | G35: 15 | H35: MDF | I35: MDF 15mm | J35: 1 | K35: =IFERROR(E35*F35,0)*J35 -> 1.44 | P35: TAMPO C/ MOLDURA 1,60 X 0,90 - AMSTERDAM
A36: 20033301 | B36: TAMPO C/ MOLDURA 1,03 X 1,03 - SANTIAGO | C36: TRAV.MAIOR 980X65(135)X15 MDF-TAMPO AMST.1,03 | D36: TRAV.MAIOR 980X65(135)X15 MDF-TAMPO AMST.1,03 | E36: 0.98 | F36: 0.065 | G36: 15 | H36: MDF | I36: MDF 15mm | J36: 2 | K36: =IFERROR(E36*F36,0)*J36 -> 0.1274 | P36: TAMPO C/ MOLDURA 1,03 X 1,03 - SANTIAGO
A37: 20033302 | B37: TAMPO C/ MOLDURA 1,03 X 1,03 - SANTIAGO | C37: TRAV. MENOR 850X65X15 MDF - TAMPO AMST. 1,03 | D37: TRAV. MENOR 850X65X15 MDF - TAMPO AMST. 1,03 | E37: 0.85 | F37: 0.065 | G37: 15 | H37: MDF | I37: MDF 15mm | J37: 2 | K37: =IFERROR(E37*F37,0)*J37 -> 0.1105 | P37: TAMPO C/ MOLDURA 1,03 X 1,03 - SANTIAGO
A38: 20033303 | B38: TAMPO C/ MOLDURA 1,03 X 1,03 - SANTIAGO | C38: MOLDURA 1030X515X15 MDF - TAMPO AMST. 1,03 | D38: MOLDURA 1030X515X15 MDF - TAMPO AMST. 1,03 | E38: 1.03 | F38: 0.515 | G38: 15 | H38: MDF | I38: MDF 15mm | J38: 2 | K38: =IFERROR(E38*F38,0)*J38 -> 1.0609 | P38: TAMPO C/ MOLDURA 1,03 X 1,03 - SANTIAGO
A39: 20033304 | B39: TAMPO C/ MOLDURA 1,03 X 1,03 - SANTIAGO | C39: TAMPO 1030X1030X15 MDF - TAMPO AMST. 1,03 | D39: TAMPO 1030X1030X15 MDF - TAMPO AMST. 1,03 | E39: 1.03 | F39: 1.03 | G39: 15 | H39: MDF | I39: MDF 15mm | J39: 1 | K39: =IFERROR(E39*F39,0)*J39 -> 1.0609 | P39: TAMPO C/ MOLDURA 1,03 X 1,03 - SANTIAGO
A40: 2002002 | B40: TAMPO LIGHT 1360X900X18 - VITREO | C40: TAMPO LIGHT 1360X900X18 - VITREO | D40: TAMPO LIGHT 1360X900X18 - VITREO | E40: 1.36 | F40: 0.9 | G40: 18 | H40: MDF | I40: MDF 18mm | J40: 1 | K40: =IFERROR(E40*F40,0)*J40 -> 1.224 | L40: =IFERROR(SUMIF(CALCULO_LOTE!$B$10:$B$59,B40,CALCULO_LOTE!$C$10:$C$59),0) -> 0 | M40: =IFERROR(L40*J40,0) -> 0 | N40: =IFERROR(M40*K40,0) -> 0 | P40: TAMPO LIGHT 1360X900X18 - VITREO
A41: 2002052 | B41: TAMPO LIGHT 1600X900X18 - VITREO | C41: TAMPO LIGHT 1600X900X18 - VITREO | D41: TAMPO LIGHT 1600X900X18 - VITREO | E41: 1.6 | F41: 0.9 | G41: 18 | H41: MDF | I41: MDF 18mm | J41: 1 | K41: =IFERROR(E41*F41,0)*J41 -> 1.44 | L41: =IFERROR(SUMIF(CALCULO_LOTE!$B$10:$B$59,B41,CALCULO_LOTE!$C$10:$C$59),0) -> 0 | M41: =IFERROR(L41*J41,0) -> 0 | N41: =IFERROR(M41*K41,0) -> 0 | P41: TAMPO LIGHT 1600X900X18 - VITREO
A42: 2002112 | B42: TAMPO LIGHT 1800X900X18 - VITREO | C42: TAMPO LIGHT 1800X900X18 - VITREO | D42: TAMPO LIGHT 1800X900X18 - VITREO | E42: 1.8 | F42: 0.9 | G42: 18 | H42: MDF | I42: MDF 18mm | J42: 1 | K42: =IFERROR(E42*F42,0)*J42 -> 1.62 | L42: =IFERROR(SUMIF(CALCULO_LOTE!$B$10:$B$59,B42,CALCULO_LOTE!$C$10:$C$59),0) -> 0 | M42: =IFERROR(L42*J42,0) -> 0 | N42: =IFERROR(M42*K42,0) -> 0 | P42: TAMPO LIGHT 1800X900X18 - VITREO
A43: 2002133 | B43: TAMPO LIGHT PLUS 1360X900X15 - VITREO | C43: TAMPO LIGHT PLUS 1360X900X15 - VITREO | D43: TAMPO LIGHT PLUS 1360X900X15 - VITREO | E43: 1.36 | F43: 0.9 | G43: 15 | H43: MDF | I43: MDF 15mm | J43: 1 | K43: =IFERROR(E43*F43,0)*J43 -> 1.224 | L43: =IFERROR(SUMIF(CALCULO_LOTE!$B$10:$B$59,B43,CALCULO_LOTE!$C$10:$C$59),0) -> 0 | M43: =IFERROR(L43*J43,0) -> 0 | N43: =IFERROR(M43*K43,0) -> 0 | P43: TAMPO LIGHT PLUS 1360X900X15 - VITREO
A44: 2002162 | B44: TAMPO C/ VIDRO LIGHT 1600X900X18MM | C44: TAMPO C/ VIDRO LIGHT 1600X900X18MM | D44: TAMPO C/ VIDRO LIGHT 1600X900X18MM | E44: 1.6 | F44: 0.9 | G44: 18 | H44: MDF | I44: MDF 18mm | J44: 1 | K44: =IFERROR(E44*F44,0)*J44 -> 1.44 | L44: =IFERROR(SUMIF(CALCULO_LOTE!$B$10:$B$59,B44,CALCULO_LOTE!$C$10:$C$59),0) -> 0 | M44: =IFERROR(L44*J44,0) -> 0 | N44: =IFERROR(M44*K44,0) -> 0 | P44: TAMPO C/ VIDRO LIGHT 1600X900X18MM
A45: 2002163 | B45: TAMPO LIGHT PLUS 1600X900X15 - VITREO | C45: TAMPO LIGHT PLUS 1600X900X15 - VITREO | D45: TAMPO LIGHT PLUS 1600X900X15 - VITREO | E45: 1.6 | F45: 0.9 | G45: 15 | H45: MDF | I45: MDF 15mm | J45: 1 | K45: =IFERROR(E45*F45,0)*J45 -> 1.44 | L45: =IFERROR(SUMIF(CALCULO_LOTE!$B$10:$B$59,B45,CALCULO_LOTE!$C$10:$C$59),0) -> 0 | M45: =IFERROR(L45*J45,0) -> 0 | N45: =IFERROR(M45*K45,0) -> 0 | P45: TAMPO LIGHT PLUS 1600X900X15 - VITREO
A46: 2002182 | B46: TAMPO C/ VIDRO LIGHT 1800X900X18MM | C46: TAMPO C/ VIDRO LIGHT 1800X900X18MM | D46: TAMPO C/ VIDRO LIGHT 1800X900X18MM | E46: 1.8 | F46: 0.9 | G46: 18 | H46: MDF | I46: MDF 18mm | J46: 1 | K46: =IFERROR(E46*F46,0)*J46 -> 1.62 | L46: =IFERROR(SUMIF(CALCULO_LOTE!$B$10:$B$59,B46,CALCULO_LOTE!$C$10:$C$59),0) -> 0 | M46: =IFERROR(L46*J46,0) -> 0 | N46: =IFERROR(M46*K46,0) -> 0 | P46: TAMPO C/ VIDRO LIGHT 1800X900X18MM
A47: 200286 | B47: TAMPO OVAL 1600X900X18 - VITREO | C47: TAMPO OVAL 1600X900X18 - VITREO | D47: TAMPO OVAL 1600X900X18 - VITREO | E47: 1.6 | F47: 0.9 | G47: 18 | H47: MDF | I47: MDF 18mm | J47: 1 | K47: =IFERROR(E47*F47,0)*J47 -> 1.44 | L47: =IFERROR(SUMIF(CALCULO_LOTE!$B$10:$B$59,B47,CALCULO_LOTE!$C$10:$C$59),0) -> 0 | M47: =IFERROR(L47*J47,0) -> 0 | N47: =IFERROR(M47*K47,0) -> 0 | P47: TAMPO OVAL 1600X900X18 - VITREO
A48: 200288 | B48: TAMPO OVAL 1800X900X18 - VITREO | C48: TAMPO OVAL 1800X900X18 - VITREO | D48: TAMPO OVAL 1800X900X18 - VITREO | E48: 1.8 | F48: 0.9 | G48: 18 | H48: MDF | I48: MDF 18mm | J48: 1 | K48: =IFERROR(E48*F48,0)*J48 -> 1.62 | L48: =IFERROR(SUMIF(CALCULO_LOTE!$B$10:$B$59,B48,CALCULO_LOTE!$C$10:$C$59),0) -> 0 | M48: =IFERROR(L48*J48,0) -> 0 | N48: =IFERROR(M48*K48,0) -> 0 | P48: TAMPO OVAL 1800X900X18 - VITREO
A49: 200296 | B49: TAMPO OVAL 1600X900X18 - C/VIDRO | C49: TAMPO OVAL 1600X900X18 - C/VIDRO | D49: TAMPO OVAL 1600X900X18 - C/VIDRO | E49: 1.6 | F49: 0.9 | G49: 18 | H49: MDF | I49: MDF 18mm | J49: 1 | K49: =IFERROR(E49*F49,0)*J49 -> 1.44 | L49: =IFERROR(SUMIF(CALCULO_LOTE!$B$10:$B$59,B49,CALCULO_LOTE!$C$10:$C$59),0) -> 0 | M49: =IFERROR(L49*J49,0) -> 0 | N49: =IFERROR(M49*K49,0) -> 0 | P49: TAMPO OVAL 1600X900X18 - C/VIDRO
...

Sheet LISTAS
A1: Produto agregado | B1: Peças unitárias | C1: m² unitário/produto | D1: Tipos de chapa usados | E1: Nomes originais agregados
A2: BASE AMSTERDAM 136 | B2: 5 | C2: 2.11 | D2: MDP 12mm, MDF 12mm | E2: BASE AMSTERDAM 136
A3: BASE BILBAO 160/180 | B3: 9 | C3: 2.62 | D3: MDP 12mm, MDF 3mm, MDF 15mm | E3: BASE BILBAO 160/180
A4: BASE BILBAO 136 | B4: 9 | C4: 2.4479 | D4: MDP 12mm, MDF 3mm, MDF 15mm | E4: BASE BILBAO
A5: BASE DUBAI 160 | B5: 9 | C5: 1.43 | D5: MDF 12mm, MDF 15mm | E5: BASE DUBAI 160
A6: BASE DUBLIN 103 | B6: 2 | C6: 1.02 | D6: MDP 12mm,MDF 25mm | E6: BASE DUBLIN 103
